Workbook

Sheet Bank_Rates
A1: Issuer | B1: Timestamp | C1: Interest Rate | D1: Duration (Days)
A2: MBB | B2: 46244 | C2: 0.018 | D2: 1
A3: MBB | B3: 46244 | C3: 0.04 | D3: 21
A4: MBB | B4: 46244 | C4: 0.065 | D4: 30
A5: MBB | B5: 46244 | C5: 0.067 | D5: 60
A6: MBB | B6: 46244 | C6: 0.07 | D6: 90
A7: MBB | B7: 46244 | C7: 0.07 | D7: 120
A8: MBB | B8: 46244 | C8: 0.07 | D8: 150
A9: MBB | B9: 46244 | C9: 0.071 | D9: 180
A10: MBB | B10: 46244 | C10: 0.071 | D10: 210
A11: MBB | B11: 46244 | C11: 0.071 | D11: 240
A12: MBB | B12: 46244 | C12: 0.071 | D12: 270
A13: MBB | B13: 46244 | C13: 0.02 | D13: 7
A14: MBB | B14: 46244 | C14: 0.03 | D14: 14

Sheet Raw_Observations
A1: Listing ID | B1: CD ID | C1: Timestamp | D1: Price ($) | E1: Value at Maturity ($) | F1: Maturity Date | G1: Remaining Duration (Days) | H1: Issuer | I1: Effective YTM | J1: Corresponding Rate | K1: Entry Spread
A2: =IF(B2<>"","L-"&TEXT(ROW()-1,"0000"),"") -> L-0001 | B2: TP03077 | C2: 46253 | D2: 4653638 | E2: 4671001 | F2: 46274 | G2: =IF(OR(C2="",F2=""),"",F2-C2) -> 21 | H2: MBB | I2: =IF(OR(D2="",E2="",G2="",G2=0),"",(E2/D2)^(365/G2)-1) -> 0.066869531 | J2: =IFERROR(SUMIFS(Bank_Rates!$C$2:$C$100,Bank_Rates!$A$2:$A$100,H2,Bank_Rates!$B$2:$B$100,LOOKUP(2,1/((Bank_Rates!$A$2:$A$100=H2)*(Bank_Rates!$B$2:$B$100<=C2)),Bank_Rates!$B$2:$B$100),Bank_Rates!$D$2:$D$100,_xlfn.AGGREGATE(14,6,Bank_Rates!$D$2:$D$100/((Bank_Rates!$A$2:$A$100=H2)*(Bank_Rates!$B$2:$B$100=LOOKUP(2,1/((Bank_Rates!$A$2:$A$100=H2)*(Bank_Rates!$B$2:$B$100<=C2)),Bank_Rates!$B$2:$B$100))*(Bank_Rates!$D$2:$D$100<=G2)),1)),"No Match") -> 0.04 | K2: =IF(OR(I2="",J2="",J2="No Match"),"",I2-J2) -> 0.026869531
A3: =IF(B3<>"","L-"&TEXT(ROW()-1,"0000"),"") -> L-0002 | B3: TP03085 | C3: 46253 | D3: 3508365 | E3: 3520202 | F3: 46272 | G3: =IF(OR(C3="",F3=""),"",F3-C3) -> 19 | H3: MBB | I3: =IF(OR(D3="",E3="",G3="",G3=0),"",(E3/D3)^(365/G3)-1) -> 0.066845322 | J3: =IFERROR(SUMIFS(Bank_Rates!$C$2:$C$100,Bank_Rates!$A$2:$A$100,H3,Bank_Rates!$B$2:$B$100,LOOKUP(2,1/((Bank_Rates!$A$2:$A$100=H3)*(Bank_Rates!$B$2:$B$100<=C3)),Bank_Rates!$B$2:$B$100),Bank_Rates!$D$2:$D$100,_xlfn.AGGREGATE(14,6,Bank_Rates!$D$2:$D$100/((Bank_Rates!$A$2:$A$100=H3)*(Bank_Rates!$B$2:$B$100=LOOKUP(2,1/((Bank_Rates!$A$2:$A$100=H3)*(Bank_Rates!$B$2:$B$100<=C3)),Bank_Rates!$B$2:$B$100))*(Bank_Rates!$D$2:$D$100<=G3)),1)),"No Match") -> 0.03 | K3: =IF(OR(I3="",J3="",J3="No Match"),"",I3-J3) -> 0.036845322
A4: =IF(B4<>"","L-"&TEXT(ROW()-1,"0000"),"") -> L-0003 | B4: TP03093 | C4: 46253 | D4: 4610986 | E4: 4626551 | F4: 46272 | G4: =IF(OR(C4="",F4=""),"",F4-C4) -> 19 | H4: MBB | I4: =IF(OR(D4="",E4="",G4="",G4=0),"",(E4/D4)^(365/G4)-1) -> 0.066879994 | J4: =IFERROR(SUMIFS(Bank_Rates!$C$2:$C$100,Bank_Rates!$A$2:$A$100,H4,Bank_Rates!$B$2:$B$100,LOOKUP(2,1/((Bank_Rates!$A$2:$A$100=H4)*(Bank_Rates!$B$2:$B$100<=C4)),Bank_Rates!$B$2:$B$100),Bank_Rates!$D$2:$D$100,_xlfn.AGGREGATE(14,6,Bank_Rates!$D$2:$D$100/((Bank_Rates!$A$2:$A$100=H4)*(Bank_Rates!$B$2:$B$100=LOOKUP(2,1/((Bank_Rates!$A$2:$A$100=H4)*(Bank_Rates!$B$2:$B$100<=C4)),Bank_Rates!$B$2:$B$100))*(Bank_Rates!$D$2:$D$100<=G4)),1)),"No Match") -> 0.03 | K4: =IF(OR(I4="",J4="",J4="No Match"),"",I4-J4) -> 0.036879994
A5: =IF(B5<>"","L-"&TEXT(ROW()-1,"0000"),"") -> L-0004 | B5: TP03104 | C5: 46253 | D5: 3508456 | E5: 3520202 | F5: 46272 | G5: =IF(OR(C5="",F5=""),"",F5-C5) -> 19 | H5: MBB | I5: =IF(OR(D5="",E5="",G5="",G5=0),"",(E5/D5)^(365/G5)-1) -> 0.06631387 | J5: =IFERROR(SUMIFS(Bank_Rates!$C$2:$C$100,Bank_Rates!$A$2:$A$100,H5,Bank_Rates!$B$2:$B$100,LOOKUP(2,1/((Bank_Rates!$A$2:$A$100=H5)*(Bank_Rates!$B$2:$B$100<=C5)),Bank_Rates!$B$2:$B$100),Bank_Rates!$D$2:$D$100,_xlfn.AGGREGATE(14,6,Bank_Rates!$D$2:$D$100/((Bank_Rates!$A$2:$A$100=H5)*(Bank_Rates!$B$2:$B$100=LOOKUP(2,1/((Bank_Rates!$A$2:$A$100=H5)*(Bank_Rates!$B$2:$B$100<=C5)),Bank_Rates!$B$2:$B$100))*(Bank_Rates!$D$2:$D$100<=G5)),1)),"No Match") -> 0.03 | K5: =IF(OR(I5="",J5="",J5="No Match"),"",I5-J5) -> 0.03631387
A6: =IF(B6<>"","L-"&TEXT(ROW()-1,"0000"),"") -> L-0005 | B6: TP00964 | C6: 46245 | D6: 6671860 | E6: 6749674 | F6: 46305 | G6: =IF(OR(C6="",F6=""),"",F6-C6) -> 60 | H6: MBB | I6: =IF(OR(D6="",E6="",G6="",G6=0),"",(E6/D6)^(365/G6)-1) -> 0.0730869 | J6: =IFERROR(SUMIFS(Bank_Rates!$C$2:$C$100,Bank_Rates!$A$2:$A$100,H6,Bank_Rates!$B$2:$B$100,LOOKUP(2,1/((Bank_Rates!$A$2:$A$100=H6)*(Bank_Rates!$B$2:$B$100<=C6)),Bank_Rates!$B$2:$B$100),Bank_Rates!$D$2:$D$100,_xlfn.AGGREGATE(14,6,Bank_Rates!$D$2:$D$100/((Bank_Rates!$A$2:$A$100=H6)*(Bank_Rates!$B$2:$B$100=LOOKUP(2,1/((Bank_Rates!$A$2:$A$100=H6)*(Bank_Rates!$B$2:$B$100<=C6)),Bank_Rates!$B$2:$B$100))*(Bank_Rates!$D$2:$D$100<=G6)),1)),"No Match") -> 0.067 | K6: =IF(OR(I6="",J6="",J6="No Match"),"",I6-J6) -> 0.0060869004
A7: =IF(B7<>"","L-"&TEXT(ROW()-1,"0000"),"") -> L-0006 | B7: TP03429 | C7: 46247 | D7: 20060000 | E7: 20826744 | F7: 46430 | G7: =IF(OR(C7="",F7=""),"",F7-C7) -> 183 | H7: MBB | I7: =IF(OR(D7="",E7="",G7="",G7=0),"",(E7/D7)^(365/G7)-1) -> 0.077685107 | J7: =IFERROR(SUMIFS(Bank_Rates!$C$2:$C$100,Bank_Rates!$A$2:$A$100,H7,Bank_Rates!$B$2:$B$100,LOOKUP(2,1/((Bank_Rates!$A$2:$A$100=H7)*(Bank_Rates!$B$2:$B$100<=C7)),Bank_Rates!$B$2:$B$100),Bank_Rates!$D$2:$D$100,_xlfn.AGGREGATE(14,6,Bank_Rates!$D$2:$D$100/((Bank_Rates!$A$2:$A$100=H7)*(Bank_Rates!$B$2:$B$100=LOOKUP(2,1/((Bank_Rates!$A$2:$A$100=H7)*(Bank_Rates!$B$2:$B$100<=C7)),Bank_Rates!$B$2:$B$100))*(Bank_Rates!$D$2:$D$100<=G7)),1)),"No Match") -> 0.071 | K7: =IF(OR(I7="",J7="",J7="No Match"),"",I7-J7) -> 0.0066851073
A8: =IF(B8<>"","L-"&TEXT(ROW()-1,"0000"),"") -> L-0007 | B8: TP00537 | C8: 46248 | D8: 29685213 | E8: 30297331 | F8: 46346 | G8: =IF(OR(C8="",F8=""),"",F8-C8) -> 98 | H8: MBB | I8: =IF(OR(D8="",E8="",G8="",G8=0),"",(E8/D8)^(365/G8)-1) -> 0.07898307 | J8: =IFERROR(SUMIFS(Bank_Rates!$C$2:$C$100,Bank_Rates!$A$2:$A$100,H8,Bank_Rates!$B$2:$B$100,LOOKUP(2,1/((Bank_Rates!$A$2:$A$100=H8)*(Bank_Rates!$B$2:$B$100<=C8)),Bank_Rates!$B$2:$B$100),Bank_Rates!$D$2:$D$100,_xlfn.AGGREGATE(14,6,Bank_Rates!$D$2:$D$100/((Bank_Rates!$A$2:$A$100=H8)*(Bank_Rates!$B$2:$B$100=LOOKUP(2,1/((Bank_Rates!$A$2:$A$100=H8)*(Bank_Rates!$B$2:$B$100<=C8)),Bank_Rates!$B$2:$B$100))*(Bank_Rates!$D$2:$D$100<=G8)),1)),"No Match") -> 0.07 | K8: =IF(OR(I8="",J8="",J8="No Match"),"",I8-J8) -> 0.0089830705
A9: =IF(B9<>"","L-"&TEXT(ROW()-1,"0000"),"") -> L-0008 | B9: TP01034 | C9: 46248 | D9: 30046000 | E9: 31206091 | F9: 46431 | G9: =IF(OR(C9="",F9=""),"",F9-C9) -> 183 | H9: MBB | I9: =IF(OR(D9="",E9="",G9="",G9=0),"",(E9/D9)^(365/G9)-1) -> 0.078488478 | J9: =IFERROR(SUMIFS(Bank_Rates!$C$2:$C$100,Bank_Rates!$A$2:$A$100,H9,Bank_Rates!$B$2:$B$100,LOOKUP(2,1/((Bank_Rates!$A$2:$A$100=H9)*(Bank_Rates!$B$2:$B$100<=C9)),Bank_Rates!$B$2:$B$100),Bank_Rates!$D$2:$D$100,_xlfn.AGGREGATE(14,6,Bank_Rates!$D$2:$D$100/((Bank_Rates!$A$2:$A$100=H9)*(Bank_Rates!$B$2:$B$100=LOOKUP(2,1/((Bank_Rates!$A$2:$A$100=H9)*(Bank_Rates!$B$2:$B$100<=C9)),Bank_Rates!$B$2:$B$100))*(Bank_Rates!$D$2:$D$100<=G9)),1)),"No Match") -> 0.071 | K9: =IF(OR(I9="",J9="",J9="No Match"),"",I9-J9) -> 0.0074884785
A10: =IF(B10<>"","L-"&TEXT(ROW()-1,"0000"),"") -> L-0009 | B10: TP00945 | C10: 46251 | D10: 20064000 | E10: 20110411 | F10: 46264 | G10: =IF(OR(C10="",F10=""),"",F10-C10) -> 13 | H10: MBB | I10: =IF(OR(D10="",E10="",G10="",G10=0),"",(E10/D10)^(365/G10)-1) -> 0.067021452 | J10: =IFERROR(SUMIFS(Bank_Rates!$C$2:$C$100,Bank_Rates!$A$2:$A$100,H10,Bank_Rates!$B$2:$B$100,LOOKUP(2,1/((Bank_Rates!$A$2:$A$100=H10)*(Bank_Rates!$B$2:$B$100<=C10)),Bank_Rates!$B$2:$B$100),Bank_Rates!$D$2:$D$100,_xlfn.AGGREGATE(14,6,Bank_Rates!$D$2:$D$100/((Bank_Rates!$A$2:$A$100=H10)*(Bank_Rates!$B$2:$B$100=LOOKUP(2,1/((Bank_Rates!$A$2:$A$100=H10)*(Bank_Rates!$B$2:$B$100<=C10)),Bank_Rates!$B$2:$B$100))*(Bank_Rates!$D$2:$D$100<=G10)),1)),"No Match") -> 0.02 | K10: =IF(OR(I10="",J10="",J10="No Match"),"",I10-J10) -> 0.047021452
A11: =IF(B11<>"","L-"&TEXT(ROW()-1,"0000"),"") -> L-0010 | B11: TP00558 | C11: 46256 | D11: 50217550 | E11: 50305612 | F11: 46266 | G11: =IF(OR(C11="",F11=""),"",F11-C11) -> 10 | H11: MBB | I11: =IF(OR(D11="",E11="",G11="",G11=0),"",(E11/D11)^(365/G11)-1) -> 0.066039853 | J11: =IFERROR(SUMIFS(Bank_Rates!$C$2:$C$100,Bank_Rates!$A$2:$A$100,H11,Bank_Rates!$B$2:$B$100,LOOKUP(2,1/((Bank_Rates!$A$2:$A$100=H11)*(Bank_Rates!$B$2:$B$100<=C11)),Bank_Rates!$B$2:$B$100),Bank_Rates!$D$2:$D$100,_xlfn.AGGREGATE(14,6,Bank_Rates!$D$2:$D$100/((Bank_Rates!$A$2:$A$100=H11)*(Bank_Rates!$B$2:$B$100=LOOKUP(2,1/((Bank_Rates!$A$2:$A$100=H11)*(Bank_Rates!$B$2:$B$100<=C11)),Bank_Rates!$B$2:$B$100))*(Bank_Rates!$D$2:$D$100<=G11)),1)),"No Match") -> 0.02 | K11: =IF(OR(I11="",J11="",J11="No Match"),"",I11-J11) -> 0.046039853
A12: =IF(B12<>"","L-"&TEXT(ROW()-1,"0000"),"") -> L-0011 | B12: TP00877 | C12: 46256 | D12: 9927097 | E12: 9963029 | F12: 46276 | G12: =IF(OR(C12="",F12=""),"",F12-C12) -> 20 | H12: MBB | I12: =IF(OR(D12="",E12="",G12="",G12=0),"",(E12/D12)^(365/G12)-1) -> 0.06816072 | J12: =IFERROR(SUMIFS(Bank_Rates!$C$2:$C$100,Bank_Rates!$A$2:$A$100,H12,Bank_Rates!$B$2:$B$100,LOOKUP(2,1/((Bank_Rates!$A$2:$A$100=H12)*(Bank_Rates!$B$2:$B$100<=C12)),Bank_Rates!$B$2:$B$100),Bank_Rates!$D$2:$D$100,_xlfn.AGGREGATE(14,6,Bank_Rates!$D$2:$D$100/((Bank_Rates!$A$2:$A$100=H12)*(Bank_Rates!$B$2:$B$100=LOOKUP(2,1/((Bank_Rates!$A$2:$A$100=H12)*(Bank_Rates!$B$2:$B$100<=C12)),Bank_Rates!$B$2:$B$100))*(Bank_Rates!$D$2:$D$100<=G12)),1)),"No Match") -> 0.03 | K12: =IF(OR(I12="",J12="",J12="No Match"),"",I12-J12) -> 0.03816072
A13: =IF(B13<>"","L-"&TEXT(ROW()-1,"0000"),"") -> L-0012 | B13: TP01801 | C13: 46256 | D13: 6557889 | E13: 6584707 | F13: 46269 | G13: =IF(OR(C13="",F13=""),"",F13-C13) -> 13 | H13: MBB | I13: =IF(OR(D13="",E13="",G13="",G13=0),"",(E13/D13)^(365/G13)-1) -> 0.12140724 | J13: =IFERROR(SUMIFS(Bank_Rates!$C$2:$C$100,Bank_Rates!$A$2:$A$100,H13,Bank_Rates!$B$2:$B$100,LOOKUP(2,1/((Bank_Rates!$A$2:$A$100=H13)*(Bank_Rates!$B$2:$B$100<=C13)),Bank_Rates!$B$2:$B$100),Bank_Rates!$D$2:$D$100,_xlfn.AGGREGATE(14,6,Bank_Rates!$D$2:$D$100/((Bank_Rates!$A$2:$A$100=H13)*(Bank_Rates!$B$2:$B$100=LOOKUP(2,1/((Bank_Rates!$A$2:$A$100=H13)*(Bank_Rates!$B$2:$B$100<=C13)),Bank_Rates!$B$2:$B$100))*(Bank_Rates!$D$2:$D$100<=G13)),1)),"No Match") -> 0.02 | K13: =IF(OR(I13="",J13="",J13="No Match"),"",I13-J13) -> 0.10140724
... A45: =IF(B45<>"","L-"&TEXT(ROW()-1,"0000"),"") -> L-0044 | B45: TP78298 | C45: 46308 | D45: 40000000 | E45: 41797721 | F45: 46489 | G45: =IF(OR(C45="",F45=""),"",F45-C45) -> 181 | H45: MBB | I45: =IF(OR(D45="",E45="",G45="",G45=0),"",(E45/D45)^(365/G45)-1) -> 0.092701841 | J45: =IFERROR(SUMIFS(Bank_Rates!$C$2:$C$100,Bank_Rates!$A$2:$A$100,H45,Bank_Rates!$B$2:$B$100,LOOKUP(2,1/((Bank_Rates!$A$2:$A$100=H45)*(Bank_Rates!$B$2:$B$100<=C45)),Bank_Rates!$B$2:$B$100),Bank_Rates!$D$2:$D$100,_xlfn.AGGREGATE(14,6,Bank_Rates!$D$2:$D$100/((Bank_Rates!$A$2:$A$100=H45)*(Bank_Rates!$B$2:$B$100=LOOKUP(2,1/((Bank_Rates!$A$2:$A$100=H45)*(Bank_Rates!$B$2:$B$100<=C45)),Bank_Rates!$B$2:$B$100))*(Bank_Rates!$D$2:$D$100<=G45)),1)),"No Match") -> 0.071 | K45: =IF(OR(I45="",J45="",J45="No Match"),"",I45-J45) -> 0.021701841
A46: =IF(B46<>"","L-"&TEXT(ROW()-1,"0000"),"") | G46: =IF(OR(C46="",F46=""),"",F46-C46) | I46: =IF(OR(D46="",E46="",G46="",G46=0),"",(E46/D46)^(365/G46)-1) | J46: =IFERROR(SUMIFS(Bank_Rates!$C$2:$C$100,Bank_Rates!$A$2:$A$100,H46,Bank_Rates!$B$2:$B$100,LOOKUP(2,1/((Bank_Rates!$A$2:$A$100=H46)*(Bank_Rates!$B$2:$B$100<=C46)),Bank_Rates!$B$2:$B$100),Bank_Rates!$D$2:$D$100,_xlfn.AGGREGATE(14,6,Bank_Rates!$D$2:$D$100/((Bank_Rates!$A$2:$A$100=H46)*(Bank_Rates!$B$2:$B$100=LOOKUP(2,1/((Bank_Rates!$A$2:$A$100=H46)*(Bank_Rates!$B$2:$B$100<=C46)),Bank_Rates!$B$2:$B$100))*(Bank_Rates!$D$2:$D$100<=G46)),1)),"No Match") -> 0 | K46: =IF(OR(I46="",J46="",J46="No Match"),"",I46-J46)
A47: =IF(B47<>"","L-"&TEXT(ROW()-1,"0000"),"") | G47: =IF(OR(C47="",F47=""),"",F47-C47) | I47: =IF(OR(D47="",E47="",G47="",G47=0),"",(E47/D47)^(365/G47)-1) | J47: =IFERROR(SUMIFS(Bank_Rates!$C$2:$C$100,Bank_Rates!$A$2:$A$100,H47,Bank_Rates!$B$2:$B$100,LOOKUP(2,1/((Bank_Rates!$A$2:$A$100=H47)*(Bank_Rates!$B$2:$B$100<=C47)),Bank_Rates!$B$2:$B$100),Bank_Rates!$D$2:$D$100,_xlfn.AGGREGATE(14,6,Bank_Rates!$D$2:$D$100/((Bank_Rates!$A$2:$A$100=H47)*(Bank_Rates!$B$2:$B$100=LOOKUP(2,1/((Bank_Rates!$A$2:$A$100=H47)*(Bank_Rates!$B$2:$B$100<=C47)),Bank_Rates!$B$2:$B$100))*(Bank_Rates!$D$2:$D$100<=G47)),1)),"No Match") -> 0 | K47: =IF(OR(I47="",J47="",J47="No Match"),"",I47-J47)
A48: =IF(B48<>"","L-"&TEXT(ROW()-1,"0000"),"") | G48: =IF(OR(C48="",F48=""),"",F48-C48) | I48: =IF(OR(D48="",E48="",G48="",G48=0),"",(E48/D48)^(365/G48)-1) | J48: =IFERROR(SUMIFS(Bank_Rates!$C$2:$C$100,Bank_Rates!$A$2:$A$100,H48,Bank_Rates!$B$2:$B$100,LOOKUP(2,1/((Bank_Rates!$A$2:$A$100=H48)*(Bank_Rates!$B$2:$B$100<=C48)),Bank_Rates!$B$2:$B$100),Bank_Rates!$D$2:$D$100,_xlfn.AGGREGATE(14,6,Bank_Rates!$D$2:$D$100/((Bank_Rates!$A$2:$A$100=H48)*(Bank_Rates!$B$2:$B$100=LOOKUP(2,1/((Bank_Rates!$A$2:$A$100=H48)*(Bank_Rates!$B$2:$B$100<=C48)),Bank_Rates!$B$2:$B$100))*(Bank_Rates!$D$2:$D$100<=G48)),1)),"No Match") -> 0 | K48: =IF(OR(I48="",J48="",J48="No Match"),"",I48-J48)
A49: =IF(B49<>"","L-"&TEXT(ROW()-1,"0000"),"") | G49: =IF(OR(C49="",F49=""),"",F49-C49) | I49: =IF(OR(D49="",E49="",G49="",G49=0),"",(E49/D49)^(365/G49)-1) | J49: =IFERROR(SUMIFS(Bank_Rates!$C$2:$C$100,Bank_Rates!$A$2:$A$100,H49,Bank_Rates!$B$2:$B$100,LOOKUP(2,1/((Bank_Rates!$A$2:$A$100=H49)*(Bank_Rates!$B$2:$B$100<=C49)),Bank_Rates!$B$2:$B$100),Bank_Rates!$D$2:$D$100,_xlfn.AGGREGATE(14,6,Bank_Rates!$D$2:$D$100/((Bank_Rates!$A$2:$A$100=H49)*(Bank_Rates!$B$2:$B$100=LOOKUP(2,1/((Bank_Rates!$A$2:$A$100=H49)*(Bank_Rates!$B$2:$B$100<=C49)),Bank_Rates!$B$2:$B$100))*(Bank_Rates!$D$2:$D$100<=G49)),1)),"No Match") -> 0 | K49: =IF(OR(I49="",J49="",J49="No Match"),"",I49-J49)
A50: =IF(B50<>"","L-"&TEXT(ROW()-1,"0000"),"") | G50: =IF(OR(C50="",F50=""),"",F50-C50) | I50: =IF(OR(D50="",E50="",G50="",G50=0),"",(E50/D50)^(365/G50)-1) | J50: =IFERROR(SUMIFS(Bank_Rates!$C$2:$C$100,Bank_Rates!$A$2:$A$100,H50,Bank_Rates!$B$2:$B$100,LOOKUP(2,1/((Bank_Rates!$A$2:$A$100=H50)*(Bank_Rates!$B$2:$B$100<=C50)),Bank_Rates!$B$2:$B$100),Bank_Rates!$D$2:$D$100,_xlfn.AGGREGATE(14,6,Bank_Rates!$D$2:$D$100/((Bank_Rates!$A$2:$A$100=H50)*(Bank_Rates!$B$2:$B$100=LOOKUP(2,1/((Bank_Rates!$A$2:$A$100=H50)*(Bank_Rates!$B$2:$B$100<=C50)),Bank_Rates!$B$2:$B$100))*(Bank_Rates!$D$2:$D$100<=G50)),1)),"No Match") -> 0 | K50: =IF(OR(I50="",J50="",J50="No Match"),"",I50-J50)
A51: =IF(B51<>"","L-"&TEXT(ROW()-1,"0000"),"") | G51: =IF(OR(C51="",F51=""),"",F51-C51) | I51: =IF(OR(D51="",E51="",G51="",G51=0),"",(E51/D51)^(365/G51)-1) | J51: =IFERROR(SUMIFS(Bank_Rates!$C$2:$C$100,Bank_Rates!$A$2:$A$100,H51,Bank_Rates!$B$2:$B$100,LOOKUP(2,1/((Bank_Rates!$A$2:$A$100=H51)*(Bank_Rates!$B$2:$B$100<=C51)),Bank_Rates!$B$2:$B$100),Bank_Rates!$D$2:$D$100,_xlfn.AGGREGATE(14,6,Bank_Rates!$D$2:$D$100/((Bank_Rates!$A$2:$A$100=H51)*(Bank_Rates!$B$2:$B$100=LOOKUP(2,1/((Bank_Rates!$A$2:$A$100=H51)*(Bank_Rates!$B$2:$B$100<=C51)),Bank_Rates!$B$2:$B$100))*(Bank_Rates!$D$2:$D$100<=G51)),1)),"No Match") -> 0 | K51: =IF(OR(I51="",J51="",J51="No Match"),"",I51-J51)
A52: =IF(B52<>"","L-"&TEXT(ROW()-1,"0000"),"") | G52: =IF(OR(C52="",F52=""),"",F52-C52) | I52: =IF(OR(D52="",E52="",G52="",G52=0),"",(E52/D52)^(365/G52)-1) | J52: =IFERROR(SUMIFS(Bank_Rates!$C$2:$C$100,Bank_Rates!$A$2:$A$100,H52,Bank_Rates!$B$2:$B$100,LOOKUP(2,1/((Bank_Rates!$A$2:$A$100=H52)*(Bank_Rates!$B$2:$B$100<=C52)),Bank_Rates!$B$2:$B$100),Bank_Rates!$D$2:$D$100,_xlfn.AGGREGATE(14,6,Bank_Rates!$D$2:$D$100/((Bank_Rates!$A$2:$A$100=H52)*(Bank_Rates!$B$2:$B$100=LOOKUP(2,1/((Bank_Rates!$A$2:$A$100=H52)*(Bank_Rates!$B$2:$B$100<=C52)),Bank_Rates!$B$2:$B$100))*(Bank_Rates!$D$2:$D$100<=G52)),1)),"No Match") -> 0 | K52: =IF(OR(I52="",J52="",J52="No Match"),"",I52-J52)
A53: =IF(B53<>"","L-"&TEXT(ROW()-1,"0000"),"") | G53: =IF(OR(C53="",F53=""),"",F53-C53) | I53: =IF(OR(D53="",E53="",G53="",G53=0),"",(E53/D53)^(365/G53)-1) | J53: =IFERROR(SUMIFS(Bank_Rates!$C$2:$C$100,Bank_Rates!$A$2:$A$100,H53,Bank_Rates!$B$2:$B$100,LOOKUP(2,1/((Bank_Rates!$A$2:$A$100=H53)*(Bank_Rates!$B$2:$B$100<=C53)),Bank_Rates!$B$2:$B$100),Bank_Rates!$D$2:$D$100,_xlfn.AGGREGATE(14,6,Bank_Rates!$D$2:$D$100/((Bank_Rates!$A$2:$A$100=H53)*(Bank_Rates!$B$2:$B$100=LOOKUP(2,1/((Bank_Rates!$A$2:$A$100=H53)*(Bank_Rates!$B$2:$B$100<=C53)),Bank_Rates!$B$2:$B$100))*(Bank_Rates!$D$2:$D$100<=G53)),1)),"No Match") -> 0 | K53: =IF(OR(I53="",J53="",J53="No Match"),"",I53-J53)
A54: =IF(B54<>"","L-"&TEXT(ROW()-1,"0000"),"") | G54: =IF(OR(C54="",F54=""),"",F54-C54) | I54: =IF(OR(D54="",E54="",G54="",G54=0),"",(E54/D54)^(365/G54)-1) | J54: =IFERROR(SUMIFS(Bank_Rates!$C$2:$C$100,Bank_Rates!$A$2:$A$100,H54,Bank_Rates!$B$2:$B$100,LOOKUP(2,1/((Bank_Rates!$A$2:$A$100=H54)*(Bank_Rates!$B$2:$B$100<=C54)),Bank_Rates!$B$2:$B$100),Bank_Rates!$D$2:$D$100,_xlfn.AGGREGATE(14,6,Bank_Rates!$D$2:$D$100/((Bank_Rates!$A$2:$A$100=H54)*(Bank_Rates!$B$2:$B$100=LOOKUP(2,1/((Bank_Rates!$A$2:$A$100=H54)*(Bank_Rates!$B$2:$B$100<=C54)),Bank_Rates!$B$2:$B$100))*(Bank_Rates!$D$2:$D$100<=G54)),1)),"No Match") -> 0 | K54: =IF(OR(I54="",J54="",J54="No Match"),"",I54-J54)
A55: =IF(B55<>"","L-"&TEXT(ROW()-1,"0000"),"") | G55: =IF(OR(C55="",F55=""),"",F55-C55) | I55: =IF(OR(D55="",E55="",G55="",G55=0),"",(E55/D55)^(365/G55)-1) | J55: =IFERROR(SUMIFS(Bank_Rates!$C$2:$C$100,Bank_Rates!$A$2:$A$100,H55,Bank_Rates!$B$2:$B$100,LOOKUP(2,1/((Bank_Rates!$A$2:$A$100=H55)*(Bank_Rates!$B$2:$B$100<=C55)),Bank_Rates!$B$2:$B$100),Bank_Rates!$D$2:$D$100,_xlfn.AGGREGATE(14,6,Bank_Rates!$D$2:$D$100/((Bank_Rates!$A$2:$A$100=H55)*(Bank_Rates!$B$2:$B$100=LOOKUP(2,1/((Bank_Rates!$A$2:$A$100=H55)*(Bank_Rates!$B$2:$B$100<=C55)),Bank_Rates!$B$2:$B$100))*(Bank_Rates!$D$2:$D$100<=G55)),1)),"No Match") -> 0 | K55: =IF(OR(I55="",J55="",J55="No Match"),"",I55-J55)
A56: =IF(B56<>"","L-"&TEXT(ROW()-1,"0000"),"") | G56: =IF(OR(C56="",F56=""),"",F56-C56) | I56: =IF(OR(D56="",E56="",G56="",G56=0),"",(E56/D56)^(365/G56)-1) | J56: =IFERROR(SUMIFS(Bank_Rates!$C$2:$C$100,Bank_Rates!$A$2:$A$100,H56,Bank_Rates!$B$2:$B$100,LOOKUP(2,1/((Bank_Rates!$A$2:$A$100=H56)*(Bank_Rates!$B$2:$B$100<=C56)),Bank_Rates!$B$2:$B$100),Bank_Rates!$D$2:$D$100,_xlfn.AGGREGATE(14,6,Bank_Rates!$D$2:$D$100/((Bank_Rates!$A$2:$A$100=H56)*(Bank_Rates!$B$2:$B$100=LOOKUP(2,1/((Bank_Rates!$A$2:$A$100=H56)*(Bank_Rates!$B$2:$B$100<=C56)),Bank_Rates!$B$2:$B$100))*(Bank_Rates!$D$2:$D$100<=G56)),1)),"No Match") -> 0 | K56: =IF(OR(I56="",J56="",J56="No Match"),"",I56-J56)
A57: =IF(B57<>"","L-"&TEXT(ROW()-1,"0000"),"") | G57: =IF(OR(C57="",F57=""),"",F57-C57) | I57: =IF(OR(D57="",E57="",G57="",G57=0),"",(E57/D57)^(365/G57)-1) | J57: =IFERROR(SUMIFS(Bank_Rates!$C$2:$C$100,Bank_Rates!$A$2:$A$100,H57,Bank_Rates!$B$2:$B$100,LOOKUP(2,1/((Bank_Rates!$A$2:$A$100=H57)*(Bank_Rates!$B$2:$B$100<=C57)),Bank_Rates!$B$2:$B$100),Bank_Rates!$D$2:$D$100,_xlfn.AGGREGATE(14,6,Bank_Rates!$D$2:$D$100/((Bank_Rates!$A$2:$A$100=H57)*(Bank_Rates!$B$2:$B$100=LOOKUP(2,1/((Bank_Rates!$A$2:$A$100=H57)*(Bank_Rates!$B$2:$B$100<=C57)),Bank_Rates!$B$2:$B$100))*(Bank_Rates!$D$2:$D$100<=G57)),1)),"No Match") -> 0 | K57: =IF(OR(I57="",J57="",J57="No Match"),"",I57-J57)
... A250: =IF(B250<>"","L-"&TEXT(ROW()-1,"0000"),"") | G250: =IF(OR(C250="",F250=""),"",F250-C250) | I250: =IF(OR(D250="",E250="",G250="",G250=0),"",(E250/D250)^(365/G250)-1) | J250: =IFERROR(SUMIFS(Bank_Rates!$C$2:$C$100,Bank_Rates!$A$2:$A$100,H250,Bank_Rates!$B$2:$B$100,LOOKUP(2,1/((Bank_Rates!$A$2:$A$100=H250)*(Bank_Rates!$B$2:$B$100<=C250)),Bank_Rates!$B$2:$B$100),Bank_Rates!$D$2:$D$100,_xlfn.AGGREGATE(14,6,Bank_Rates!$D$2:$D$100/((Bank_Rates!$A$2:$A$100=H250)*(Bank_Rates!$B$2:$B$100=LOOKUP(2,1/((Bank_Rates!$A$2:$A$100=H250)*(Bank_Rates!$B$2:$B$100<=C250)),Bank_Rates!$B$2:$B$100))*(Bank_Rates!$D$2:$D$100<=G250)),1)),"No Match") -> 0 | K250: =IF(OR(I250="",J250="",J250="No Match"),"",I250-J250)

Sheet Pricing
A1: Listing ID | B1: CD ID | C1: Value at Maturity ($) | D1: Remaining Days | E1: Corresponding Rate | F1: Entry Spread | G1: Liquidity Spread | H1: Pricing Yield | I1: Model Price ($) | J1: Effective Return
A2: L-0001 | B2: TP03077 | C2: =IFERROR(LOOKUP(2,1/((Raw_Observations!$A$2:$A$250=A2)*(Raw_Observations!$B$2:$B$250=B2)),Raw_Observations!$E$2:$E$250),"") -> 4671001 | D2: =IFERROR(MAX(0,LOOKUP(2,1/((Raw_Observations!$A$2:$A$250=A2)*(Raw_Observations!$B$2:$B$250=B2)),Raw_Observations!$F$2:$F$250)-TODAY()),"") -> 0 | E2: =IFERROR(LOOKUP(2,1/((Raw_Observations!$A$2:$A$999=A3)*(Raw_Observations!$B$2:$B$999=B3)),Raw_Observations!$J$2:$J$999),"No Match") -> 0.03 | F2: =IFERROR(LOOKUP(2,1/((Raw_Observations!$A$2:$A$250=A2)*(Raw_Observations!$B$2:$B$250=B2)),Raw_Observations!$K$2:$K$250),"") -> 0.026869531 | G2: 0.02 | H2: =IF(OR(E2="",G2="",E2="No Match"),"",E2+G2) -> 0.05 | I2: =IF(OR(C2="",D2="",H2=""),"",C2/((1+H2)^(D2/365))) -> 4671001 | J2: =IFERROR((I2/LOOKUP(2,1/((Raw_Observations!$A$2:$A$999=A2)*(Raw_Observations!$B$2:$B$999=B2)),Raw_Observations!$D$2:$D$999))^365-1,"") -> 2.8934765
A3: L-0002 | B3: TP03085 | C3: =IFERROR(LOOKUP(2,1/((Raw_Observations!$A$2:$A$250=A3)*(Raw_Observations!$B$2:$B$250=B3)),Raw_Observations!$E$2:$E$250),"") -> 3520202 | D3: =IFERROR(MAX(0,LOOKUP(2,1/((Raw_Observations!$A$2:$A$250=A3)*(Raw_Observations!$B$2:$B$250=B3)),Raw_Observations!$F$2:$F$250)-TODAY()),"") -> 0 | E3: =IFERROR(LOOKUP(2,1/((Raw_Observations!$A$2:$A$999=A4)*(Raw_Observations!$B$2:$B$999=B4)),Raw_Observations!$J$2:$J$999),"No Match") -> 0.03 | F3: =IFERROR(LOOKUP(2,1/((Raw_Observations!$A$2:$A$250=A3)*(Raw_Observations!$B$2:$B$250=B3)),Raw_Observations!$K$2:$K$250),"") -> 0.036845322 | G3: 0.02 | H3: =IF(OR(E3="",G3="",E3="No Match"),"",E3+G3) -> 0.05 | I3: =IF(OR(C3="",D3="",H3=""),"",C3/((1+H3)^(D3/365))) -> 3520202 | J3: =IFERROR((I3/LOOKUP(2,1/((Raw_Observations!$A$2:$A$999=A3)*(Raw_Observations!$B$2:$B$999=B3)),Raw_Observations!$D$2:$D$999))^365-1,"") -> 2.419225
A4: L-0003 | B4: TP03093 | C4: =IFERROR(LOOKUP(2,1/((Raw_Observations!$A$2:$A$250=A4)*(Raw_Observations!$B$2:$B$250=B4)),Raw_Observations!$E$2:$E$250),"") -> 4626551 | D4: =IFERROR(MAX(0,LOOKUP(2,1/((Raw_Observations!$A$2:$A$250=A4)*(Raw_Observations!$B$2:$B$250=B4)),Raw_Observations!$F$2:$F$250)-TODAY()),"") -> 0 | E4: =IFERROR(LOOKUP(2,1/((Raw_Observations!$A$2:$A$999=A4)*(Raw_Observations!$B$2:$B$999=B4)),Raw_Observations!$J$2:$J$999),"No Match") -> 0.03 | F4: =IFERROR(LOOKUP(2,1/((Raw_Observations!$A$2:$A$250=A4)*(Raw_Observations!$B$2:$B$250=B4)),Raw_Observations!$K$2:$K$250),"") -> 0.036879994 | G4: 0.02 | H4: =IF(OR(E4="",G4="",E4="No Match"),"",E4+G4) -> 0.05 | I4: =IF(OR(C4="",D4="",H4=""),"",C4/((1+H4)^(D4/365))) -> 4626551 | J4: =IFERROR((I4/LOOKUP(2,1/((Raw_Observations!$A$2:$A$999=A4)*(Raw_Observations!$B$2:$B$999=B4)),Raw_Observations!$D$2:$D$999))^365-1,"") -> 2.421337
A5: L-0004 | B5: TP03104 | C5: =IFERROR(LOOKUP(2,1/((Raw_Observations!$A$2:$A$250=A5)*(Raw_Observations!$B$2:$B$250=B5)),Raw_Observations!$E$2:$E$250),"") -> 3520202 | D5: =IFERROR(MAX(0,LOOKUP(2,1/((Raw_Observations!$A$2:$A$250=A5)*(Raw_Observations!$B$2:$B$250=B5)),Raw_Observations!$F$2:$F$250)-TODAY()),"") -> 0 | E5: =IFERROR(LOOKUP(2,1/((Raw_Observations!$A$2:$A$999=A5)*(Raw_Observations!$B$2:$B$999=B5)),Raw_Observations!$J$2:$J$999),"No Match") -> 0.03 | F5: =IFERROR(LOOKUP(2,1/((Raw_Observations!$A$2:$A$250=A5)*(Raw_Observations!$B$2:$B$250=B5)),Raw_Observations!$K$2:$K$250),"") -> 0.03631387 | G5: 0.02 | H5: =IF(OR(E5="",G5="",E5="No Match"),"",E5+G5) -> 0.05 | I5: =IF(OR(C5="",D5="",H5=""),"",C5/((1+H5)^(D5/365))) -> 3520202 | J5: =IFERROR((I5/LOOKUP(2,1/((Raw_Observations!$A$2:$A$999=A5)*(Raw_Observations!$B$2:$B$999=B5)),Raw_Observations!$D$2:$D$999))^365-1,"") -> 2.3870071
A6: L-0005 | B6: TP00964 | C6: =IFERROR(LOOKUP(2,1/((Raw_Observations!$A$2:$A$250=A6)*(Raw_Observations!$B$2:$B$250=B6)),Raw_Observations!$E$2:$E$250),"") -> 6749674 | D6: =IFERROR(MAX(0,LOOKUP(2,1/((Raw_Observations!$A$2:$A$250=A6)*(Raw_Observations!$B$2:$B$250=B6)),Raw_Observations!$F$2:$F$250)-TODAY()),"") -> 0 | E6: =IFERROR(LOOKUP(2,1/((Raw_Observations!$A$2:$A$999=A6)*(Raw_Observations!$B$2:$B$999=B6)),Raw_Observations!$J$2:$J$999),"No Match") -> 0.067 | F6: =IFERROR(LOOKUP(2,1/((Raw_Observations!$A$2:$A$250=A6)*(Raw_Observations!$B$2:$B$250=B6)),Raw_Observations!$K$2:$K$250),"") -> 0.0060869004 | G6: 0.002 | H6: =IF(OR(E6="",G6="",E6="No Match"),"",E6+G6) -> 0.069 | I6: =IF(OR(C6="",D6="",H6=""),"",C6/((1+H6)^(D6/365))) -> 6749674 | J6: =IFERROR((I6/LOOKUP(2,1/((Raw_Observations!$A$2:$A$999=A6)*(Raw_Observations!$B$2:$B$999=B6)),Raw_Observations!$D$2:$D$999))^365-1,"") -> 67.880073
A7: L-0006 | B7: TP03429 | C7: =IFERROR(LOOKUP(2,1/((Raw_Observations!$A$2:$A$250=A7)*(Raw_Observations!$B$2:$B$250=B7)),Raw_Observations!$E$2:$E$250),"") -> 20826744 | D7: =IFERROR(MAX(0,LOOKUP(2,1/((Raw_Observations!$A$2:$A$250=A7)*(Raw_Observations!$B$2:$B$250=B7)),Raw_Observations!$F$2:$F$250)-TODAY()),"") -> 122 | E7: =IFERROR(LOOKUP(2,1/((Raw_Observations!$A$2:$A$999=A7)*(Raw_Observations!$B$2:$B$999=B7)),Raw_Observations!$J$2:$J$999),"No Match") -> 0.071 | F7: =IFERROR(LOOKUP(2,1/((Raw_Observations!$A$2:$A$250=A7)*(Raw_Observations!$B$2:$B$250=B7)),Raw_Observations!$K$2:$K$250),"") -> 0.0066851073 | G7: 0.003 | H7: =IF(OR(E7="",G7="",E7="No Match"),"",E7+G7) -> 0.074 | I7: =IF(OR(C7="",D7="",H7=""),"",C7/((1+H7)^(D7/365))) -> 20335661 | J7: =IFERROR((I7/LOOKUP(2,1/((Raw_Observations!$A$2:$A$999=A7)*(Raw_Observations!$B$2:$B$999=B7)),Raw_Observations!$D$2:$D$999))^365-1,"") -> 144.71087
A8: L-0007 | B8: TP00537 | C8: =IFERROR(LOOKUP(2,1/((Raw_Observations!$A$2:$A$250=A8)*(Raw_Observations!$B$2:$B$250=B8)),Raw_Observations!$E$2:$E$250),"") -> 30297331 | D8: =IFERROR(MAX(0,LOOKUP(2,1/((Raw_Observations!$A$2:$A$250=A8)*(Raw_Observations!$B$2:$B$250=B8)),Raw_Observations!$F$2:$F$250)-TODAY()),"") -> 38 | E8: =IFERROR(LOOKUP(2,1/((Raw_Observations!$A$2:$A$999=A8)*(Raw_Observations!$B$2:$B$999=B8)),Raw_Observations!$J$2:$J$999),"No Match") -> 0.07 | F8: =IFERROR(LOOKUP(2,1/((Raw_Observations!$A$2:$A$250=A8)*(Raw_Observations!$B$2:$B$250=B8)),Raw_Observations!$K$2:$K$250),"") -> 0.0089830705 | G8: 0.0034 | H8: =IF(OR(E8="",G8="",E8="No Match"),"",E8+G8) -> 0.0734 | I8: =IF(OR(C8="",D8="",H8=""),"",C8/((1+H8)^(D8/365))) -> 30074734 | J8: =IFERROR((I8/LOOKUP(2,1/((Raw_Observations!$A$2:$A$999=A8)*(Raw_Observations!$B$2:$B$999=B8)),Raw_Observations!$D$2:$D$999))^365-1,"") -> 115.54492
A9: L-0008 | B9: TP01034 | C9: =IFERROR(LOOKUP(2,1/((Raw_Observations!$A$2:$A$250=A9)*(Raw_Observations!$B$2:$B$250=B9)),Raw_Observations!$E$2:$E$250),"") -> 31206091 | D9: =IFERROR(MAX(0,LOOKUP(2,1/((Raw_Observations!$A$2:$A$250=A9)*(Raw_Observations!$B$2:$B$250=B9)),Raw_Observations!$F$2:$F$250)-TODAY()),"") -> 123 | E9: =IFERROR(LOOKUP(2,1/((Raw_Observations!$A$2:$A$999=A9)*(Raw_Observations!$B$2:$B$999=B9)),Raw_Observations!$J$2:$J$999),"No Match") -> 0.071 | F9: =IFERROR(LOOKUP(2,1/((Raw_Observations!$A$2:$A$250=A9)*(Raw_Observations!$B$2:$B$250=B9)),Raw_Observations!$K$2:$K$250),"") -> 0.0074884785 | G9: 0.003 | H9: =IF(OR(E9="",G9="",E9="No Match"),"",E9+G9) -> 0.074 | I9: =IF(OR(C9="",D9="",H9=""),"",C9/((1+H9)^(D9/365))) -> 30464310 | J9: =IFERROR((I9/LOOKUP(2,1/((Raw_Observations!$A$2:$A$999=A9)*(Raw_Observations!$B$2:$B$999=B9)),Raw_Observations!$D$2:$D$999))^365-1,"") -> 154.49331
A10: L-0009 | B10: TP00945 | C10: =IFERROR(LOOKUP(2,1/((Raw_Observations!$A$2:$A$250=A10)*(Raw_Observations!$B$2:$B$250=B10)),Raw_Observations!$E$2:$E$250),"") -> 20110411 | D10: =IFERROR(MAX(0,LOOKUP(2,1/((Raw_Observations!$A$2:$A$250=A10)*(Raw_Observations!$B$2:$B$250=B10)),Raw_Observations!$F$2:$F$250)-TODAY()),"") -> 0 | E10: =IFERROR(LOOKUP(2,1/((Raw_Observations!$A$2:$A$999=A10)*(Raw_Observations!$B$2:$B$999=B10)),Raw_Observations!$J$2:$J$999),"No Match") -> 0.02 | F10: =IFERROR(LOOKUP(2,1/((Raw_Observations!$A$2:$A$250=A10)*(Raw_Observations!$B$2:$B$250=B10)),Raw_Observations!$K$2:$K$250),"") -> 0.047021452 | G10: 0.01 | H10: =IF(OR(E10="",G10="",E10="No Match"),"",E10+G10) -> 0.03 | I10: =IF(OR(C10="",D10="",H10=""),"",C10/((1+H10)^(D10/365))) -> 20110411 | J10: =IFERROR((I10/LOOKUP(2,1/((Raw_Observations!$A$2:$A$999=A10)*(Raw_Observations!$B$2:$B$999=B10)),Raw_Observations!$D$2:$D$999))^365-1,"") -> 1.3240794
A11: L-0010 | B11: TP00558 | C11: =IFERROR(LOOKUP(2,1/((Raw_Observations!$A$2:$A$250=A11)*(Raw_Observations!$B$2:$B$250=B11)),Raw_Observations!$E$2:$E$250),"") -> 50305612 | D11: =IFERROR(MAX(0,LOOKUP(2,1/((Raw_Observations!$A$2:$A$250=A11)*(Raw_Observations!$B$2:$B$250=B11)),Raw_Observations!$F$2:$F$250)-TODAY()),"") -> 0 | E11: =IFERROR(LOOKUP(2,1/((Raw_Observations!$A$2:$A$999=A11)*(Raw_Observations!$B$2:$B$999=B11)),Raw_Observations!$J$2:$J$999),"No Match") -> 0.02 | F11: =IFERROR(LOOKUP(2,1/((Raw_Observations!$A$2:$A$250=A11)*(Raw_Observations!$B$2:$B$250=B11)),Raw_Observations!$K$2:$K$250),"") -> 0.046039853 | G11: 0.017 | H11: =IF(OR(E11="",G11="",E11="No Match"),"",E11+G11) -> 0.037 | I11: =IF(OR(C11="",D11="",H11=""),"",C11/((1+H11)^(D11/365))) -> 50305612 | J11: =IFERROR((I11/LOOKUP(2,1/((Raw_Observations!$A$2:$A$999=A11)*(Raw_Observations!$B$2:$B$999=B11)),Raw_Observations!$D$2:$D$999))^365-1,"") -> 0.89554635
A12: L-0011 | B12: TP00877 | C12: =IFERROR(LOOKUP(2,1/((Raw_Observations!$A$2:$A$250=A12)*(Raw_Observations!$B$2:$B$250=B12)),Raw_Observations!$E$2:$E$250),"") -> 9963029 | D12: =IFERROR(MAX(0,LOOKUP(2,1/((Raw_Observations!$A$2:$A$250=A12)*(Raw_Observations!$B$2:$B$250=B12)),Raw_Observations!$F$2:$F$250)-TODAY()),"") -> 0 | E12: =IFERROR(LOOKUP(2,1/((Raw_Observations!$A$2:$A$999=A12)*(Raw_Observations!$B$2:$B$999=B12)),Raw_Observations!$J$2:$J$999),"No Match") -> 0.03 | F12: =IFERROR(LOOKUP(2,1/((Raw_Observations!$A$2:$A$250=A12)*(Raw_Observations!$B$2:$B$250=B12)),Raw_Observations!$K$2:$K$250),"") -> 0.03816072 | G12: 0.017 | H12: =IF(OR(E12="",G12="",E12="No Match"),"",E12+G12) -> 0.047 | I12: =IF(OR(C12="",D12="",H12=""),"",C12/((1+H12)^(D12/365))) -> 9963029 | J12: =IFERROR((I12/LOOKUP(2,1/((Raw_Observations!$A$2:$A$999=A12)*(Raw_Observations!$B$2:$B$999=B12)),Raw_Observations!$D$2:$D$999))^365-1,"") -> 2.7387986
A13: L-0012 | B13: TP01801 | C13: =IFERROR(LOOKUP(2,1/((Raw_Observations!$A$2:$A$250=A13)*(Raw_Observations!$B$2:$B$250=B13)),Raw_Observations!$E$2:$E$250),"") -> 6584707 | D13: =IFERROR(MAX(0,LOOKUP(2,1/((Raw_Observations!$A$2:$A$250=A13)*(Raw_Observations!$B$2:$B$250=B13)),Raw_Observations!$F$2:$F$250)-TODAY()),"") -> 0 | E13: =IFERROR(LOOKUP(2,1/((Raw_Observations!$A$2:$A$999=A13)*(Raw_Observations!$B$2:$B$999=B13)),Raw_Observations!$J$2:$J$999),"No Match") -> 0.02 | F13: =IFERROR(LOOKUP(2,1/((Raw_Observations!$A$2:$A$250=A13)*(Raw_Observations!$B$2:$B$250=B13)),Raw_Observations!$K$2:$K$250),"") -> 0.10140724 | G13: 0.017 | H13: =IF(OR(E13="",G13="",E13="No Match"),"",E13+G13) -> 0.037 | I13: =IF(OR(C13="",D13="",H13=""),"",C13/((1+H13)^(D13/365))) -> 6584707 | J13: =IFERROR((I13/LOOKUP(2,1/((Raw_Observations!$A$2:$A$999=A13)*(Raw_Observations!$B$2:$B$999=B13)),Raw_Observations!$D$2:$D$999))^365-1,"") -> 3.4353062
A14: L-0013 | B14: TP00397 | C14: =IFERROR(LOOKUP(2,1/((Raw_Observations!$A$2:$A$250=A14)*(Raw_Observations!$B$2:$B$250=B14)),Raw_Observations!$E$2:$E$250),"") -> 4574570 | D14: =IFERROR(MAX(0,LOOKUP(2,1/((Raw_Observations!$A$2:$A$250=A14)*(Raw_Observations!$B$2:$B$250=B14)),Raw_Observations!$F$2:$F$250)-TODAY()),"") -> 0 | E14: =IFERROR(LOOKUP(2,1/((Raw_Observations!$A$2:$A$999=A14)*(Raw_Observations!$B$2:$B$999=B14)),Raw_Observations!$J$2:$J$999),"No Match") -> 0.04 | F14: =IFERROR(LOOKUP(2,1/((Raw_Observations!$A$2:$A$250=A14)*(Raw_Observations!$B$2:$B$250=B14)),Raw_Observations!$K$2:$K$250),"") -> 0.026926527 | G14: 0.017 | H14: =IF(OR(E14="",G14="",E14="No Match"),"",E14+G14) -> 0.057 | I14: =IF(OR(C14="",D14="",H14=""),"",C14/((1+H14)^(D14/365))) -> 4574570 | J14: =IFERROR((I14/LOOKUP(2,1/((Raw_Observations!$A$2:$A$999=A14)*(Raw_Observations!$B$2:$B$999=B14)),Raw_Observations!$D$2:$D$999))^365-1,"") -> 4.0508309
A15: L-0014 | B15: TP93098 | C15: =IFERROR(LOOKUP(2,1/((Raw_Observations!$A$2:$A$250=A15)*(Raw_Observations!$B$2:$B$250=B15)),Raw_Observations!$E$2:$E$250),"") -> 51993393 | D15: =IFERROR(MAX(0,LOOKUP(2,1/((Raw_Observations!$A$2:$A$250=A15)*(Raw_Observations!$B$2:$B$250=B15)),Raw_Observations!$F$2:$F$250)-TODAY()),"") -> 131 | E15: =IFERROR(LOOKUP(2,1/((Raw_Observations!$A$2:$A$999=A15)*(Raw_Observations!$B$2:$B$999=B15)),Raw_Observations!$J$2:$J$999),"No Match") -> 0.071 | F15: =IFERROR(LOOKUP(2,1/((Raw_Observations!$A$2:$A$250=A15)*(Raw_Observations!$B$2:$B$250=B15)),Raw_Observations!$K$2:$K$250),"") -> 0.011432327 | G15: 0.0093 | H15: =IF(OR(E15="",G15="",E15="No Match"),"",E15+G15) -> 0.0803 | I15: =IF(OR(C15="",D15="",H15=""),"",C15/((1+H15)^(D15/365))) -> 50571862 | J15: =IFERROR((I15/LOOKUP(2,1/((Raw_Observations!$A$2:$A$999=A15)*(Raw_Observations!$B$2:$B$999=B15)),Raw_Observations!$D$2:$D$999))^365-1,"") -> 78.620473
... A22: L-0021 | B22: TP00665 | C22: =IFERROR(LOOKUP(2,1/((Raw_Observations!$A$2:$A$250=A22)*(Raw_Observations!$B$2:$B$250=B22)),Raw_Observations!$E$2:$E$250),"") -> 15030272 | D22: =IFERROR(MAX(0,LOOKUP(2,1/((Raw_Observations!$A$2:$A$250=A22)*(Raw_Observations!$B$2:$B$250=B22)),Raw_Observations!$F$2:$F$250)-TODAY()),"") -> 0 | E22: =IFERROR(LOOKUP(2,1/((Raw_Observations!$A$2:$A$999=A22)*(Raw_Observations!$B$2:$B$999=B22)),Raw_Observations!$J$2:$J$999),"No Match") -> 0.03 | F22: =IFERROR(LOOKUP(2,1/((Raw_Observations!$A$2:$A$250=A22)*(Raw_Observations!$B$2:$B$250=B22)),Raw_Observations!$K$2:$K$250),"") -> 0.031642019 | G22: 0.0295 | H22: =IF(OR(E22="",G22="",E22="No Match"),"",E22+G22) -> 0.0595 | I22: =IF(OR(C22="",D22="",H22=""),"",C22/((1+H22)^(D22/365))) -> 15030272 | J22: =IFERROR((I22/LOOKUP(2,1/((Raw_Observations!$A$2:$A$999=A22)*(Raw_Observations!$B$2:$B$999=B22)),Raw_Observations!$D$2:$D$999))^365-1,"") -> 1.9349843
A23: L-0025 | B23: TP51686 | C23: =IFERROR(LOOKUP(2,1/((Raw_Observations!$A$2:$A$250=A23)*(Raw_Observations!$B$2:$B$250=B23)),Raw_Observations!$E$2:$E$250),"") -> 52225917 | D23: =IFERROR(MAX(0,LOOKUP(2,1/((Raw_Observations!$A$2:$A$250=A23)*(Raw_Observations!$B$2:$B$250=B23)),Raw_Observations!$F$2:$F$250)-TODAY()),"") -> 179 | E23: =IFERROR(LOOKUP(2,1/((Raw_Observations!$A$2:$A$999=A24)*(Raw_Observations!$B$2:$B$999=B24)),Raw_Observations!$J$2:$J$999),"No Match") -> 0.071 | F23: =IFERROR(LOOKUP(2,1/((Raw_Observations!$A$2:$A$250=A23)*(Raw_Observations!$B$2:$B$250=B23)),Raw_Observations!$K$2:$K$250),"") -> 0.022053441 | G23: 0.0208 | H23: =IF(OR(E23="",G23="",E23="No Match"),"",E23+G23) -> 0.0918 | I23: =IF(OR(C23="",D23="",H23=""),"",C23/((1+H23)^(D23/365))) -> 50024215 | J23: =IFERROR((I23/LOOKUP(2,1/((Raw_Observations!$A$2:$A$999=A23)*(Raw_Observations!$B$2:$B$999=B23)),Raw_Observations!$D$2:$D$999))^365-1,"") -> 0.34226459
A24: L-0026 | B24: TP03038 | C24: =IFERROR(LOOKUP(2,1/((Raw_Observations!$A$2:$A$250=A24)*(Raw_Observations!$B$2:$B$250=B24)),Raw_Observations!$E$2:$E$250),"") -> 52242252 | D24: =IFERROR(MAX(0,LOOKUP(2,1/((Raw_Observations!$A$2:$A$250=A24)*(Raw_Observations!$B$2:$B$250=B24)),Raw_Observations!$F$2:$F$250)-TODAY()),"") -> 179 | E24: =IFERROR(LOOKUP(2,1/((Raw_Observations!$A$2:$A$999=A25)*(Raw_Observations!$B$2:$B$999=B25)),Raw_Observations!$J$2:$J$999),"No Match") -> 0.071 | F24: =IFERROR(LOOKUP(2,1/((Raw_Observations!$A$2:$A$250=A24)*(Raw_Observations!$B$2:$B$250=B24)),Raw_Observations!$K$2:$K$250),"") -> 0.022076615 | G24: 0.0208 | H24: =IF(OR(E24="",G24="",E24="No Match"),"",E24+G24) -> 0.0918 | I24: =IF(OR(C24="",D24="",H24=""),"",C24/((1+H24)^(D24/365))) -> 50039862 | J24: =IFERROR((I24/LOOKUP(2,1/((Raw_Observations!$A$2:$A$999=A24)*(Raw_Observations!$B$2:$B$999=B24)),Raw_Observations!$D$2:$D$999))^365-1,"") -> 0.34739661
A25: L-0027 | B25: TP00403 | C25: =IFERROR(LOOKUP(2,1/((Raw_Observations!$A$2:$A$250=A25)*(Raw_Observations!$B$2:$B$250=B25)),Raw_Observations!$E$2:$E$250),"") -> 52372315 | D25: =IFERROR(MAX(0,LOOKUP(2,1/((Raw_Observations!$A$2:$A$250=A25)*(Raw_Observations!$B$2:$B$250=B25)),Raw_Observations!$F$2:$F$250)-TODAY()),"") -> 180 | E25: =IFERROR(LOOKUP(2,1/((Raw_Observations!$A$2:$A$999=A26)*(Raw_Observations!$B$2:$B$999=B26)),Raw_Observations!$J$2:$J$999),"No Match") -> 0.071 | F25: =IFERROR(LOOKUP(2,1/((Raw_Observations!$A$2:$A$250=A25)*(Raw_Observations!$B$2:$B$250=B25)),Raw_Observations!$K$2:$K$250),"") -> 0.021969745 | G25: 0.0208 | H25: =IF(OR(E25="",G25="",E25="No Match"),"",E25+G25) -> 0.0918 | I25: =IF(OR(C25="",D25="",H25=""),"",C25/((1+H25)^(D25/365))) -> 50152372 | J25: =IFERROR((I25/LOOKUP(2,1/((Raw_Observations!$A$2:$A$999=A25)*(Raw_Observations!$B$2:$B$999=B25)),Raw_Observations!$D$2:$D$999))^365-1,"") -> 0.32530912
A26: L-0028 | B26: TP96004 | C26: =IFERROR(LOOKUP(2,1/((Raw_Observations!$A$2:$A$250=A26)*(Raw_Observations!$B$2:$B$250=B26)),Raw_Observations!$E$2:$E$250),"") -> 52295424 | D26: =IFERROR(MAX(0,LOOKUP(2,1/((Raw_Observations!$A$2:$A$250=A26)*(Raw_Observations!$B$2:$B$250=B26)),Raw_Observations!$F$2:$F$250)-TODAY()),"") -> 179 | E26: =IFERROR(LOOKUP(2,1/((Raw_Observations!$A$2:$A$999=A27)*(Raw_Observations!$B$2:$B$999=B27)),Raw_Observations!$J$2:$J$999),"No Match") -> 0.071 | F26: =IFERROR(LOOKUP(2,1/((Raw_Observations!$A$2:$A$250=A26)*(Raw_Observations!$B$2:$B$250=B26)),Raw_Observations!$K$2:$K$250),"") -> 0.021983125 | G26: 0.0208 | H26: =IF(OR(E26="",G26="",E26="No Match"),"",E26+G26) -> 0.0918 | I26: =IF(OR(C26="",D26="",H26=""),"",C26/((1+H26)^(D26/365))) -> 50090792 | J26: =IFERROR((I26/LOOKUP(2,1/((Raw_Observations!$A$2:$A$999=A26)*(Raw_Observations!$B$2:$B$999=B26)),Raw_Observations!$D$2:$D$999))^365-1,"") -> 0.32681112
A27: L-0029 | B27: TP51250 | C27: =IFERROR(LOOKUP(2,1/((Raw_Observations!$A$2:$A$250=A27)*(Raw_Observations!$B$2:$B$250=B27)),Raw_Observations!$E$2:$E$250),"") -> 52266726 | D27: =IFERROR(MAX(0,LOOKUP(2,1/((Raw_Observations!$A$2:$A$250=A27)*(Raw_Observations!$B$2:$B$250=B27)),Raw_Observations!$F$2:$F$250)-TODAY()),"") -> 180 | E27: =IFERROR(LOOKUP(2,1/((Raw_Observations!$A$2:$A$999=A28)*(Raw_Observations!$B$2:$B$999=B28)),Raw_Observations!$J$2:$J$999),"No Match") -> 0.071 | F27: =IFERROR(LOOKUP(2,1/((Raw_Observations!$A$2:$A$250=A27)*(Raw_Observations!$B$2:$B$250=B27)),Raw_Observations!$K$2:$K$250),"") -> 0.021939763 | G27: 0.0208 | H27: =IF(OR(E27="",G27="",E27="No Match"),"",E27+G27) -> 0.0918 | I27: =IF(OR(C27="",D27="",H27=""),"",C27/((1+H27)^(D27/365))) -> 50051259 | J27: =IFERROR((I27/LOOKUP(2,1/((Raw_Observations!$A$2:$A$999=A27)*(Raw_Observations!$B$2:$B$999=B27)),Raw_Observations!$D$2:$D$999))^365-1,"") -> 0.3187451
A28: L-0030 | B28: TP22853 | C28: =IFERROR(LOOKUP(2,1/((Raw_Observations!$A$2:$A$250=A28)*(Raw_Observations!$B$2:$B$250=B28)),Raw_Observations!$E$2:$E$250),"") -> 52256593 | D28: =IFERROR(MAX(0,LOOKUP(2,1/((Raw_Observations!$A$2:$A$250=A28)*(Raw_Observations!$B$2:$B$250=B28)),Raw_Observations!$F$2:$F$250)-TODAY()),"") -> 180 | E28: =IFERROR(LOOKUP(2,1/((Raw_Observations!$A$2:$A$999=A29)*(Raw_Observations!$B$2:$B$999=B29)),Raw_Observations!$J$2:$J$999),"No Match") -> 0.071 | F28: =IFERROR(LOOKUP(2,1/((Raw_Observations!$A$2:$A$250=A28)*(Raw_Observations!$B$2:$B$250=B28)),Raw_Observations!$K$2:$K$250),"") -> 0.022055997 | G28: 0.02198 | H28: =IF(OR(E28="",G28="",E28="No Match"),"",E28+G28) -> 0.09298 | I28: =IF(OR(C28="",D28="",H28=""),"",C28/((1+H28)^(D28/365))) -> 50014905 | J28: =IFERROR((I28/LOOKUP(2,1/((Raw_Observations!$A$2:$A$999=A28)*(Raw_Observations!$B$2:$B$999=B28)),Raw_Observations!$D$2:$D$999))^365-1,"") -> 0.10682192
A29: L-0031 | B29: TP01183 | C29: =IFERROR(LOOKUP(2,1/((Raw_Observations!$A$2:$A$250=A29)*(Raw_Observations!$B$2:$B$250=B29)),Raw_Observations!$E$2:$E$250),"") -> 34463041 | D29: =IFERROR(MAX(0,LOOKUP(2,1/((Raw_Observations!$A$2:$A$250=A29)*(Raw_Observations!$B$2:$B$250=B29)),Raw_Observations!$F$2:$F$250)-TODAY()),"") -> 179 | E29: =IFERROR(LOOKUP(2,1/((Raw_Observations!$A$2:$A$999=A30)*(Raw_Observations!$B$2:$B$999=B30)),Raw_Observations!$J$2:$J$999),"No Match") -> 0.071 | F29: =IFERROR(LOOKUP(2,1/((Raw_Observations!$A$2:$A$250=A29)*(Raw_Observations!$B$2:$B$250=B29)),Raw_Observations!$K$2:$K$250),"") -> 0.021889685 | G29: 0.0208 | H29: =IF(OR(E29="",G29="",E29="No Match"),"",E29+G29) -> 0.0918 | I29: =IF(OR(C29="",D29="",H29=""),"",C29/((1+H29)^(D29/365))) -> 33010174 | J29: =IFERROR((I29/LOOKUP(2,1/((Raw_Observations!$A$2:$A$999=A29)*(Raw_Observations!$B$2:$B$999=B29)),Raw_Observations!$D$2:$D$999))^365-1,"") -> 0.30654915
A30: L-0032 | B30: TP03921 | C30: =IFERROR(LOOKUP(2,1/((Raw_Observations!$A$2:$A$250=A30)*(Raw_Observations!$B$2:$B$250=B30)),Raw_Observations!$E$2:$E$250),"") -> 34443606 | D30: =IFERROR(MAX(0,LOOKUP(2,1/((Raw_Observations!$A$2:$A$250=A30)*(Raw_Observations!$B$2:$B$250=B30)),Raw_Observations!$F$2:$F$250)-TODAY()),"") -> 179 | E30: =IFERROR(LOOKUP(2,1/((Raw_Observations!$A$2:$A$999=A31)*(Raw_Observations!$B$2:$B$999=B31)),Raw_Observations!$J$2:$J$999),"No Match") -> 0.071 | F30: =IFERROR(LOOKUP(2,1/((Raw_Observations!$A$2:$A$250=A30)*(Raw_Observations!$B$2:$B$250=B30)),Raw_Observations!$K$2:$K$250),"") -> 0.021849216 | G30: 0.0208 | H30: =IF(OR(E30="",G30="",E30="No Match"),"",E30+G30) -> 0.0918 | I30: =IF(OR(C30="",D30="",H30=""),"",C30/((1+H30)^(D30/365))) -> 32991558 | J30: =IFERROR((I30/LOOKUP(2,1/((Raw_Observations!$A$2:$A$999=A30)*(Raw_Observations!$B$2:$B$999=B30)),Raw_Observations!$D$2:$D$999))^365-1,"") -> 0.29786935
A31: L-0033 | B31: TP00975 | C31: =IFERROR(LOOKUP(2,1/((Raw_Observations!$A$2:$A$250=A31)*(Raw_Observations!$B$2:$B$250=B31)),Raw_Observations!$E$2:$E$250),"") -> 34475656 | D31: =IFERROR(MAX(0,LOOKUP(2,1/((Raw_Observations!$A$2:$A$250=A31)*(Raw_Observations!$B$2:$B$250=B31)),Raw_Observations!$F$2:$F$250)-TODAY()),"") -> 179 | E31: 0.071 | F31: =IFERROR(LOOKUP(2,1/((Raw_Observations!$A$2:$A$250=A31)*(Raw_Observations!$B$2:$B$250=B31)),Raw_Observations!$K$2:$K$250),"") -> 0.02176037 | G31: 0.0208 | H31: =IF(OR(E31="",G31="",E31="No Match"),"",E31+G31) -> 0.0918 | I31: =IF(OR(C31="",D31="",H31=""),"",C31/((1+H31)^(D31/365))) -> 33022257 | J31: =IFERROR((I31/LOOKUP(2,1/((Raw_Observations!$A$2:$A$999=A31)*(Raw_Observations!$B$2:$B$999=B31)),Raw_Observations!$D$2:$D$999))^365-1,"") -> 0.27901444
C32: =IFERROR(LOOKUP(2,1/((Raw_Observations!$A$2:$A$250=A32)*(Raw_Observations!$B$2:$B$250=B32)),Raw_Observations!$E$2:$E$250),"") -> 0 | D32: =IFERROR(MAX(0,LOOKUP(2,1/((Raw_Observations!$A$2:$A$250=A32)*(Raw_Observations!$B$2:$B$250=B32)),Raw_Observations!$F$2:$F$250)-TODAY()),"") -> 0 | E32: =IFERROR(LOOKUP(2,1/((Raw_Observations!$A$2:$A$999=A33)*(Raw_Observations!$B$2:$B$999=B33)),Raw_Observations!$J$2:$J$999),"No Match") -> 0 | F32: =IFERROR(LOOKUP(2,1/((Raw_Observations!$A$2:$A$250=A32)*(Raw_Observations!$B$2:$B$250=B32)),Raw_Observations!$K$2:$K$250),"") | H32: =IF(OR(E32="",G32="",E32="No Match"),"",E32+G32) | I32: =IF(OR(C32="",D32="",H32=""),"",C32/((1+H32)^(D32/365))) | J32: =IFERROR((I32/LOOKUP(2,1/((Raw_Observations!$A$2:$A$999=A32)*(Raw_Observations!$B$2:$B$999=B32)),Raw_Observations!$D$2:$D$999))^365-1,"")
C33: =IFERROR(LOOKUP(2,1/((Raw_Observations!$A$2:$A$250=A33)*(Raw_Observations!$B$2:$B$250=B33)),Raw_Observations!$E$2:$E$250),"") -> 0 | D33: =IFERROR(MAX(0,LOOKUP(2,1/((Raw_Observations!$A$2:$A$250=A33)*(Raw_Observations!$B$2:$B$250=B33)),Raw_Observations!$F$2:$F$250)-TODAY()),"") -> 0 | E33: =IF(OR(A33="",B33=""),"",IFERROR(SUMIFS(Bank_Rates!$C$2:$C$100,Bank_Rates!$A$2:$A$100,LOOKUP(2,1/((Raw_Observations!$A$2:$A$250=A33)*(Raw_Observations!$B$2:$B$250=B33)),Raw_Observations!$H$2:$H$250),Bank_Rates!$B$2:$B$100,MAXIFS(Bank_Rates!$B$2:$B$100,Bank_Rates!$A$2:$A$100,LOOKUP(2,1/((Raw_Observations!$A$2:$A$250=A33)*(Raw_Observations!$B$2:$B$250=B33)),Raw_Observations!$H$2:$H$250),Bank_Rates!$B$2:$B$100,"<="&TODAY()),Bank_Rates!$D$2:$D$100,MAXIFS(Bank_Rates!$D$2:$D$100,Bank_Rates!$A$2:$A$100,LOOKUP(2,1/((Raw_Observations!$A$2:$A$250=A33)*(Raw_Observations!$B$2:$B$250=B33)),Raw_Observations!$H$2:$H$250),Bank_Rates!$B$2:$B$100,MAXIFS(Bank_Rates!$B$2:$B$100,Bank_Rates!$A$2:$A$100,LOOKUP(2,1/((Raw_Observations!$A$2:$A$250=A33)*(Raw_Observations!$B$2:$B$250=B33)),Raw_Observations!$H$2:$H$250),Bank_Rates!$B$2:$B$100,"<="&TODAY()),Bank_Rates!$D$2:$D$100,"<="&D33)),"No Match")) | F33: =IFERROR(LOOKUP(2,1/((Raw_Observations!$A$2:$A$250=A33)*(Raw_Observations!$B$2:$B$250=B33)),Raw_Observations!$K$2:$K$250),"") | H33: =IF(OR(E33="",G33="",E33="No Match"),"",E33+G33) | I33: =IF(OR(C33="",D33="",H33=""),"",C33/((1+H33)^(D33/365))) | J33: =IFERROR((I33/LOOKUP(2,1/((Raw_Observations!$A$2:$A$999=A33)*(Raw_Observations!$B$2:$B$999=B33)),Raw_Observations!$D$2:$D$999))^365-1,"")
C34: =IFERROR(LOOKUP(2,1/((Raw_Observations!$A$2:$A$250=A34)*(Raw_Observations!$B$2:$B$250=B34)),Raw_Observations!$E$2:$E$250),"") -> 0 | D34: =IFERROR(MAX(0,LOOKUP(2,1/((Raw_Observations!$A$2:$A$250=A34)*(Raw_Observations!$B$2:$B$250=B34)),Raw_Observations!$F$2:$F$250)-TODAY()),"") -> 0 | E34: =IF(OR(A34="",B34=""),"",IFERROR(SUMIFS(Bank_Rates!$C$2:$C$100,Bank_Rates!$A$2:$A$100,LOOKUP(2,1/((Raw_Observations!$A$2:$A$250=A34)*(Raw_Observations!$B$2:$B$250=B34)),Raw_Observations!$H$2:$H$250),Bank_Rates!$B$2:$B$100,MAXIFS(Bank_Rates!$B$2:$B$100,Bank_Rates!$A$2:$A$100,LOOKUP(2,1/((Raw_Observations!$A$2:$A$250=A34)*(Raw_Observations!$B$2:$B$250=B34)),Raw_Observations!$H$2:$H$250),Bank_Rates!$B$2:$B$100,"<="&TODAY()),Bank_Rates!$D$2:$D$100,MAXIFS(Bank_Rates!$D$2:$D$100,Bank_Rates!$A$2:$A$100,LOOKUP(2,1/((Raw_Observations!$A$2:$A$250=A34)*(Raw_Observations!$B$2:$B$250=B34)),Raw_Observations!$H$2:$H$250),Bank_Rates!$B$2:$B$100,MAXIFS(Bank_Rates!$B$2:$B$100,Bank_Rates!$A$2:$A$100,LOOKUP(2,1/((Raw_Observations!$A$2:$A$250=A34)*(Raw_Observations!$B$2:$B$250=B34)),Raw_Observations!$H$2:$H$250),Bank_Rates!$B$2:$B$100,"<="&TODAY()),Bank_Rates!$D$2:$D$100,"<="&D34)),"No Match")) | F34: =IFERROR(LOOKUP(2,1/((Raw_Observations!$A$2:$A$250=A34)*(Raw_Observations!$B$2:$B$250=B34)),Raw_Observations!$K$2:$K$250),"") | H34: =IF(OR(E34="",G34="",E34="No Match"),"",E34+G34) | I34: =IF(OR(C34="",D34="",H34=""),"",C34/((1+H34)^(D34/365))) | J34: =IFERROR((I34/LOOKUP(2,1/((Raw_Observations!$A$2:$A$999=A34)*(Raw_Observations!$B$2:$B$999=B34)),Raw_Observations!$D$2:$D$999))^365-1,"")
C35: =IFERROR(LOOKUP(2,1/((Raw_Observations!$A$2:$A$250=A35)*(Raw_Observations!$B$2:$B$250=B35)),Raw_Observations!$E$2:$E$250),"") -> 0 | D35: =IFERROR(MAX(0,LOOKUP(2,1/((Raw_Observations!$A$2:$A$250=A35)*(Raw_Observations!$B$2:$B$250=B35)),Raw_Observations!$F$2:$F$250)-TODAY()),"") -> 0 | E35: =IF(OR(A35="",B35=""),"",IFERROR(SUMIFS(Bank_Rates!$C$2:$C$100,Bank_Rates!$A$2:$A$100,LOOKUP(2,1/((Raw_Observations!$A$2:$A$250=A35)*(Raw_Observations!$B$2:$B$250=B35)),Raw_Observations!$H$2:$H$250),Bank_Rates!$B$2:$B$100,MAXIFS(Bank_Rates!$B$2:$B$100,Bank_Rates!$A$2:$A$100,LOOKUP(2,1/((Raw_Observations!$A$2:$A$250=A35)*(Raw_Observations!$B$2:$B$250=B35)),Raw_Observations!$H$2:$H$250),Bank_Rates!$B$2:$B$100,"<="&TODAY()),Bank_Rates!$D$2:$D$100,MAXIFS(Bank_Rates!$D$2:$D$100,Bank_Rates!$A$2:$A$100,LOOKUP(2,1/((Raw_Observations!$A$2:$A$250=A35)*(Raw_Observations!$B$2:$B$250=B35)),Raw_Observations!$H$2:$H$250),Bank_Rates!$B$2:$B$100,MAXIFS(Bank_Rates!$B$2:$B$100,Bank_Rates!$A$2:$A$100,LOOKUP(2,1/((Raw_Observations!$A$2:$A$250=A35)*(Raw_Observations!$B$2:$B$250=B35)),Raw_Observations!$H$2:$H$250),Bank_Rates!$B$2:$B$100,"<="&TODAY()),Bank_Rates!$D$2:$D$100,"<="&D35)),"No Match")) | F35: =IFERROR(LOOKUP(2,1/((Raw_Observations!$A$2:$A$250=A35)*(Raw_Observations!$B$2:$B$250=B35)),Raw_Observations!$K$2:$K$250),"") | H35: =IF(OR(E35="",G35="",E35="No Match"),"",E35+G35) | I35: =IF(OR(C35="",D35="",H35=""),"",C35/((1+H35)^(D35/365))) | J35: =IFERROR((I35/LOOKUP(2,1/((Raw_Observations!$A$2:$A$999=A35)*(Raw_Observations!$B$2:$B$999=B35)),Raw_Observations!$D$2:$D$999))^365-1,"")
C36: =IFERROR(LOOKUP(2,1/((Raw_Observations!$A$2:$A$250=A36)*(Raw_Observations!$B$2:$B$250=B36)),Raw_Observations!$E$2:$E$250),"") -> 0 | D36: =IFERROR(MAX(0,LOOKUP(2,1/((Raw_Observations!$A$2:$A$250=A36)*(Raw_Observations!$B$2:$B$250=B36)),Raw_Observations!$F$2:$F$250)-TODAY()),"") -> 0 | E36: =IF(OR(A36="",B36=""),"",IFERROR(SUMIFS(Bank_Rates!$C$2:$C$100,Bank_Rates!$A$2:$A$100,LOOKUP(2,1/((Raw_Observations!$A$2:$A$250=A36)*(Raw_Observations!$B$2:$B$250=B36)),Raw_Observations!$H$2:$H$250),Bank_Rates!$B$2:$B$100,MAXIFS(Bank_Rates!$B$2:$B$100,Bank_Rates!$A$2:$A$100,LOOKUP(2,1/((Raw_Observations!$A$2:$A$250=A36)*(Raw_Observations!$B$2:$B$250=B36)),Raw_Observations!$H$2:$H$250),Bank_Rates!$B$2:$B$100,"<="&TODAY()),Bank_Rates!$D$2:$D$100,MAXIFS(Bank_Rates!$D$2:$D$100,Bank_Rates!$A$2:$A$100,LOOKUP(2,1/((Raw_Observations!$A$2:$A$250=A36)*(Raw_Observations!$B$2:$B$250=B36)),Raw_Observations!$H$2:$H$250),Bank_Rates!$B$2:$B$100,MAXIFS(Bank_Rates!$B$2:$B$100,Bank_Rates!$A$2:$A$100,LOOKUP(2,1/((Raw_Observations!$A$2:$A$250=A36)*(Raw_Observations!$B$2:$B$250=B36)),Raw_Observations!$H$2:$H$250),Bank_Rates!$B$2:$B$100,"<="&TODAY()),Bank_Rates!$D$2:$D$100,"<="&D36)),"No Match")) | F36: =IFERROR(LOOKUP(2,1/((Raw_Observations!$A$2:$A$250=A36)*(Raw_Observations!$B$2:$B$250=B36)),Raw_Observations!$K$2:$K$250),"") | H36: =IF(OR(E36="",G36="",E36="No Match"),"",E36+G36) | I36: =IF(OR(C36="",D36="",H36=""),"",C36/((1+H36)^(D36/365))) | J36: =IFERROR((I36/LOOKUP(2,1/((Raw_Observations!$A$2:$A$999=A36)*(Raw_Observations!$B$2:$B$999=B36)),Raw_Observations!$D$2:$D$999))^365-1,"")
C37: =IFERROR(LOOKUP(2,1/((Raw_Observations!$A$2:$A$250=A37)*(Raw_Observations!$B$2:$B$250=B37)),Raw_Observations!$E$2:$E$250),"") -> 0 | D37: =IFERROR(MAX(0,LOOKUP(2,1/((Raw_Observations!$A$2:$A$250=A37)*(Raw_Observations!$B$2:$B$250=B37)),Raw_Observations!$F$2:$F$250)-TODAY()),"") -> 0 | E37: =IF(OR(A37="",B37=""),"",IFERROR(SUMIFS(Bank_Rates!$C$2:$C$100,Bank_Rates!$A$2:$A$100,LOOKUP(2,1/((Raw_Observations!$A$2:$A$250=A37)*(Raw_Observations!$B$2:$B$250=B37)),Raw_Observations!$H$2:$H$250),Bank_Rates!$B$2:$B$100,MAXIFS(Bank_Rates!$B$2:$B$100,Bank_Rates!$A$2:$A$100,LOOKUP(2,1/((Raw_Observations!$A$2:$A$250=A37)*(Raw_Observations!$B$2:$B$250=B37)),Raw_Observations!$H$2:$H$250),Bank_Rates!$B$2:$B$100,"<="&TODAY()),Bank_Rates!$D$2:$D$100,MAXIFS(Bank_Rates!$D$2:$D$100,Bank_Rates!$A$2:$A$100,LOOKUP(2,1/((Raw_Observations!$A$2:$A$250=A37)*(Raw_Observations!$B$2:$B$250=B37)),Raw_Observations!$H$2:$H$250),Bank_Rates!$B$2:$B$100,MAXIFS(Bank_Rates!$B$2:$B$100,Bank_Rates!$A$2:$A$100,LOOKUP(2,1/((Raw_Observations!$A$2:$A$250=A37)*(Raw_Observations!$B$2:$B$250=B37)),Raw_Observations!$H$2:$H$250),Bank_Rates!$B$2:$B$100,"<="&TODAY()),Bank_Rates!$D$2:$D$100,"<="&D37)),"No Match")) | F37: =IFERROR(LOOKUP(2,1/((Raw_Observations!$A$2:$A$250=A37)*(Raw_Observations!$B$2:$B$250=B37)),Raw_Observations!$K$2:$K$250),"") | H37: =IF(OR(E37="",G37="",E37="No Match"),"",E37+G37) | I37: =IF(OR(C37="",D37="",H37=""),"",C37/((1+H37)^(D37/365))) | J37: =IFERROR((I37/LOOKUP(2,1/((Raw_Observations!$A$2:$A$999=A37)*(Raw_Observations!$B$2:$B$999=B37)),Raw_Observations!$D$2:$D$999))^365-1,"")
C38: =IFERROR(LOOKUP(2,1/((Raw_Observations!$A$2:$A$250=A38)*(Raw_Observations!$B$2:$B$250=B38)),Raw_Observations!$E$2:$E$250),"") -> 0 | D38: =IFERROR(MAX(0,LOOKUP(2,1/((Raw_Observations!$A$2:$A$250=A38)*(Raw_Observations!$B$2:$B$250=B38)),Raw_Observations!$F$2:$F$250)-TODAY()),"") -> 0 | E38: =IF(OR(A38="",B38=""),"",IFERROR(SUMIFS(Bank_Rates!$C$2:$C$100,Bank_Rates!$A$2:$A$100,LOOKUP(2,1/((Raw_Observations!$A$2:$A$250=A38)*(Raw_Observations!$B$2:$B$250=B38)),Raw_Observations!$H$2:$H$250),Bank_Rates!$B$2:$B$100,MAXIFS(Bank_Rates!$B$2:$B$100,Bank_Rates!$A$2:$A$100,LOOKUP(2,1/((Raw_Observations!$A$2:$A$250=A38)*(Raw_Observations!$B$2:$B$250=B38)),Raw_Observations!$H$2:$H$250),Bank_Rates!$B$2:$B$100,"<="&TODAY()),Bank_Rates!$D$2:$D$100,MAXIFS(Bank_Rates!$D$2:$D$100,Bank_Rates!$A$2:$A$100,LOOKUP(2,1/((Raw_Observations!$A$2:$A$250=A38)*(Raw_Observations!$B$2:$B$250=B38)),Raw_Observations!$H$2:$H$250),Bank_Rates!$B$2:$B$100,MAXIFS(Bank_Rates!$B$2:$B$100,Bank_Rates!$A$2:$A$100,LOOKUP(2,1/((Raw_Observations!$A$2:$A$250=A38)*(Raw_Observations!$B$2:$B$250=B38)),Raw_Observations!$H$2:$H$250),Bank_Rates!$B$2:$B$100,"<="&TODAY()),Bank_Rates!$D$2:$D$100,"<="&D38)),"No Match")) | F38: =IFERROR(LOOKUP(2,1/((Raw_Observations!$A$2:$A$250=A38)*(Raw_Observations!$B$2:$B$250=B38)),Raw_Observations!$K$2:$K$250),"") | H38: =IF(OR(E38="",G38="",E38="No Match"),"",E38+G38) | I38: =IF(OR(C38="",D38="",H38=""),"",C38/((1+H38)^(D38/365))) | J38: =IFERROR((I38/LOOKUP(2,1/((Raw_Observations!$A$2:$A$999=A38)*(Raw_Observations!$B$2:$B$999=B38)),Raw_Observations!$D$2:$D$999))^365-1,"")
C39: =IFERROR(LOOKUP(2,1/((Raw_Observations!$A$2:$A$250=A39)*(Raw_Observations!$B$2:$B$250=B39)),Raw_Observations!$E$2:$E$250),"") -> 0 | D39: =IFERROR(MAX(0,LOOKUP(2,1/((Raw_Observations!$A$2:$A$250=A39)*(Raw_Observations!$B$2:$B$250=B39)),Raw_Observations!$F$2:$F$250)-TODAY()),"") -> 0 | E39: =IF(OR(A39="",B39=""),"",IFERROR(SUMIFS(Bank_Rates!$C$2:$C$100,Bank_Rates!$A$2:$A$100,LOOKUP(2,1/((Raw_Observations!$A$2:$A$250=A39)*(Raw_Observations!$B$2:$B$250=B39)),Raw_Observations!$H$2:$H$250),Bank_Rates!$B$2:$B$100,MAXIFS(Bank_Rates!$B$2:$B$100,Bank_Rates!$A$2:$A$100,LOOKUP(2,1/((Raw_Observations!$A$2:$A$250=A39)*(Raw_Observations!$B$2:$B$250=B39)),Raw_Observations!$H$2:$H$250),Bank_Rates!$B$2:$B$100,"<="&TODAY()),Bank_Rates!$D$2:$D$100,MAXIFS(Bank_Rates!$D$2:$D$100,Bank_Rates!$A$2:$A$100,LOOKUP(2,1/((Raw_Observations!$A$2:$A$250=A39)*(Raw_Observations!$B$2:$B$250=B39)),Raw_Observations!$H$2:$H$250),Bank_Rates!$B$2:$B$100,MAXIFS(Bank_Rates!$B$2:$B$100,Bank_Rates!$A$2:$A$100,LOOKUP(2,1/((Raw_Observations!$A$2:$A$250=A39)*(Raw_Observations!$B$2:$B$250=B39)),Raw_Observations!$H$2:$H$250),Bank_Rates!$B$2:$B$100,"<="&TODAY()),Bank_Rates!$D$2:$D$100,"<="&D39)),"No Match")) | F39: =IFERROR(LOOKUP(2,1/((Raw_Observations!$A$2:$A$250=A39)*(Raw_Observations!$B$2:$B$250=B39)),Raw_Observations!$K$2:$K$250),"") | H39: =IF(OR(E39="",G39="",E39="No Match"),"",E39+G39) | I39: =IF(OR(C39="",D39="",H39=""),"",C39/((1+H39)^(D39/365))) | J39: =IFERROR((I39/LOOKUP(2,1/((Raw_Observations!$A$2:$A$999=A39)*(Raw_Observations!$B$2:$B$999=B39)),Raw_Observations!$D$2:$D$999))^365-1,"")
C40: =IFERROR(LOOKUP(2,1/((Raw_Observations!$A$2:$A$250=A40)*(Raw_Observations!$B$2:$B$250=B40)),Raw_Observations!$E$2:$E$250),"") -> 0 | D40: =IFERROR(MAX(0,LOOKUP(2,1/((Raw_Observations!$A$2:$A$250=A40)*(Raw_Observations!$B$2:$B$250=B40)),Raw_Observations!$F$2:$F$250)-TODAY()),"") -> 0 | E40: =IF(OR(A40="",B40=""),"",IFERROR(SUMIFS(Bank_Rates!$C$2:$C$100,Bank_Rates!$A$2:$A$100,LOOKUP(2,1/((Raw_Observations!$A$2:$A$250=A40)*(Raw_Observations!$B$2:$B$250=B40)),Raw_Observations!$H$2:$H$250),Bank_Rates!$B$2:$B$100,MAXIFS(Bank_Rates!$B$2:$B$100,Bank_Rates!$A$2:$A$100,LOOKUP(2,1/((Raw_Observations!$A$2:$A$250=A40)*(Raw_Observations!$B$2:$B$250=B40)),Raw_Observations!$H$2:$H$250),Bank_Rates!$B$2:$B$100,"<="&TODAY()),Bank_Rates!$D$2:$D$100,MAXIFS(Bank_Rates!$D$2:$D$100,Bank_Rates!$A$2:$A$100,LOOKUP(2,1/((Raw_Observations!$A$2:$A$250=A40)*(Raw_Observations!$B$2:$B$250=B40)),Raw_Observations!$H$2:$H$250),Bank_Rates!$B$2:$B$100,MAXIFS(Bank_Rates!$B$2:$B$100,Bank_Rates!$A$2:$A$100,LOOKUP(2,1/((Raw_Observations!$A$2:$A$250=A40)*(Raw_Observations!$B$2:$B$250=B40)),Raw_Observations!$H$2:$H$250),Bank_Rates!$B$2:$B$100,"<="&TODAY()),Bank_Rates!$D$2:$D$100,"<="&D40)),"No Match")) | F40: =IFERROR(LOOKUP(2,1/((Raw_Observations!$A$2:$A$250=A40)*(Raw_Observations!$B$2:$B$250=B40)),Raw_Observations!$K$2:$K$250),"") | H40: =IF(OR(E40="",G40="",E40="No Match"),"",E40+G40) | I40: =IF(OR(C40="",D40="",H40=""),"",C40/((1+H40)^(D40/365))) | J40: =IFERROR((I40/LOOKUP(2,1/((Raw_Observations!$A$2:$A$999=A40)*(Raw_Observations!$B$2:$B$999=B40)),Raw_Observations!$D$2:$D$999))^365-1,"")
C41: =IFERROR(LOOKUP(2,1/((Raw_Observations!$A$2:$A$250=A41)*(Raw_Observations!$B$2:$B$250=B41)),Raw_Observations!$E$2:$E$250),"") -> 0 | D41: =IFERROR(MAX(0,LOOKUP(2,1/((Raw_Observations!$A$2:$A$250=A41)*(Raw_Observations!$B$2:$B$250=B41)),Raw_Observations!$F$2:$F$250)-TODAY()),"") -> 0 | E41: =IF(OR(A41="",B41=""),"",IFERROR(SUMIFS(Bank_Rates!$C$2:$C$100,Bank_Rates!$A$2:$A$100,LOOKUP(2,1/((Raw_Observations!$A$2:$A$250=A41)*(Raw_Observations!$B$2:$B$250=B41)),Raw_Observations!$H$2:$H$250),Bank_Rates!$B$2:$B$100,MAXIFS(Bank_Rates!$B$2:$B$100,Bank_Rates!$A$2:$A$100,LOOKUP(2,1/((Raw_Observations!$A$2:$A$250=A41)*(Raw_Observations!$B$2:$B$250=B41)),Raw_Observations!$H$2:$H$250),Bank_Rates!$B$2:$B$100,"<="&TODAY()),Bank_Rates!$D$2:$D$100,MAXIFS(Bank_Rates!$D$2:$D$100,Bank_Rates!$A$2:$A$100,LOOKUP(2,1/((Raw_Observations!$A$2:$A$250=A41)*(Raw_Observations!$B$2:$B$250=B41)),Raw_Observations!$H$2:$H$250),Bank_Rates!$B$2:$B$100,MAXIFS(Bank_Rates!$B$2:$B$100,Bank_Rates!$A$2:$A$100,LOOKUP(2,1/((Raw_Observations!$A$2:$A$250=A41)*(Raw_Observations!$B$2:$B$250=B41)),Raw_Observations!$H$2:$H$250),Bank_Rates!$B$2:$B$100,"<="&TODAY()),Bank_Rates!$D$2:$D$100,"<="&D41)),"No Match")) | F41: =IFERROR(LOOKUP(2,1/((Raw_Observations!$A$2:$A$250=A41)*(Raw_Observations!$B$2:$B$250=B41)),Raw_Observations!$K$2:$K$250),"") | H41: =IF(OR(E41="",G41="",E41="No Match"),"",E41+G41) | I41: =IF(OR(C41="",D41="",H41=""),"",C41/((1+H41)^(D41/365))) | J41: =IFERROR((I41/LOOKUP(2,1/((Raw_Observations!$A$2:$A$999=A41)*(Raw_Observations!$B$2:$B$999=B41)),Raw_Observations!$D$2:$D$999))^365-1,"")
C42: =IFERROR(LOOKUP(2,1/((Raw_Observations!$A$2:$A$250=A42)*(Raw_Observations!$B$2:$B$250=B42)),Raw_Observations!$E$2:$E$250),"") -> 0 | D42: =IFERROR(MAX(0,LOOKUP(2,1/((Raw_Observations!$A$2:$A$250=A42)*(Raw_Observations!$B$2:$B$250=B42)),Raw_Observations!$F$2:$F$250)-TODAY()),"") -> 0 | E42: =IF(OR(A42="",B42=""),"",IFERROR(SUMIFS(Bank_Rates!$C$2:$C$100,Bank_Rates!$A$2:$A$100,LOOKUP(2,1/((Raw_Observations!$A$2:$A$250=A42)*(Raw_Observations!$B$2:$B$250=B42)),Raw_Observations!$H$2:$H$250),Bank_Rates!$B$2:$B$100,MAXIFS(Bank_Rates!$B$2:$B$100,Bank_Rates!$A$2:$A$100,LOOKUP(2,1/((Raw_Observations!$A$2:$A$250=A42)*(Raw_Observations!$B$2:$B$250=B42)),Raw_Observations!$H$2:$H$250),Bank_Rates!$B$2:$B$100,"<="&TODAY()),Bank_Rates!$D$2:$D$100,MAXIFS(Bank_Rates!$D$2:$D$100,Bank_Rates!$A$2:$A$100,LOOKUP(2,1/((Raw_Observations!$A$2:$A$250=A42)*(Raw_Observations!$B$2:$B$250=B42)),Raw_Observations!$H$2:$H$250),Bank_Rates!$B$2:$B$100,MAXIFS(Bank_Rates!$B$2:$B$100,Bank_Rates!$A$2:$A$100,LOOKUP(2,1/((Raw_Observations!$A$2:$A$250=A42)*(Raw_Observations!$B$2:$B$250=B42)),Raw_Observations!$H$2:$H$250),Bank_Rates!$B$2:$B$100,"<="&TODAY()),Bank_Rates!$D$2:$D$100,"<="&D42)),"No Match")) | F42: =IFERROR(LOOKUP(2,1/((Raw_Observations!$A$2:$A$250=A42)*(Raw_Observations!$B$2:$B$250=B42)),Raw_Observations!$K$2:$K$250),"") | H42: =IF(OR(E42="",G42="",E42="No Match"),"",E42+G42) | I42: =IF(OR(C42="",D42="",H42=""),"",C42/((1+H42)^(D42/365))) | J42: =IFERROR((I42/LOOKUP(2,1/((Raw_Observations!$A$2:$A$999=A42)*(Raw_Observations!$B$2:$B$999=B42)),Raw_Observations!$D$2:$D$999))^365-1,"")
