Workbook

Sheet Bank_Rates
A1: Issuer | B1: Timestamp | C1: Interest Rate | D1: Duration (Days)
A2: MBB | B2: 46244 | C2: 0.018 | D2: 1
A3: MBB | B3: 46244 | C3: 0.04 | D3: 7
A4: MBB | B4: 46244 | C4: 0.065 | D4: 30
A5: MBB | B5: 46244 | C5: 0.067 | D5: 60
A6: MBB | B6: 46244 | C6: 0.07 | D6: 90
A7: MBB | B7: 46244 | C7: 0.07 | D7: 120
A8: MBB | B8: 46244 | C8: 0.07 | D8: 150
A9: MBB | B9: 46244 | C9: 0.071 | D9: 180
A10: MBB | B10: 46244 | C10: 0.071 | D10: 210
A11: MBB | B11: 46244 | C11: 0.071 | D11: 240
A12: MBB | B12: 46244 | C12: 0.071 | D12: 270

Sheet Raw_Observations
A1: Listing ID | B1: CD ID | C1: Timestamp | D1: Price ($) | E1: Value at Maturity ($) | F1: Maturity Date | G1: Remaining Duration (Days) | H1: Issuer | I1: Effective YTM | J1: Corresponding Rate | K1: Entry Spread
A2: =IF(B2<>"","L-"&TEXT(ROW()-1,"0000"),"") -> L-0001 | B2: TP03077 | C2: 46253 | D2: 4653638 | E2: 4671001 | F2: 46274 | G2: =RawObservationsTable[[#This Row],[Maturity Date]]-RawObservationsTable[[#This Row],[Timestamp]] -> 21 | H2: MBB | I2: =(RawObservationsTable[[#This Row],[Value at Maturity ($)]]/RawObservationsTable[[#This Row],[Price ($)]])^(365/RawObservationsTable[[#This Row],[Remaining Duration (Days)]])-1 -> 0.066869531 | J2: =IFERROR(LOOKUP(2,1/((Bank_Rates!$A$2:$A$100=H2)*(Bank_Rates!$B$2:$B$100=LOOKUP(2,1/((Bank_Rates!$A$2:$A$100=H2)*(Bank_Rates!$B$2:$B$100<=C2)),Bank_Rates!$B$2:$B$100))*(Bank_Rates!$D$2:$D$100<=G2)),Bank_Rates!$C$2:$C$100),"No Match") -> 0.04 | K2: =IF(OR(I2="",J2=""),"",I2-J2) -> 0.026869531
A3: =IF(B3<>"","L-"&TEXT(ROW()-1,"0000"),"") -> L-0002 | B3: TP03085 | C3: 46253 | D3: 3508365 | E3: 3520202 | F3: 46272 | G3: =RawObservationsTable[[#This Row],[Maturity Date]]-RawObservationsTable[[#This Row],[Timestamp]] -> 19 | H3: MBB | I3: =(RawObservationsTable[[#This Row],[Value at Maturity ($)]]/RawObservationsTable[[#This Row],[Price ($)]])^(365/RawObservationsTable[[#This Row],[Remaining Duration (Days)]])-1 -> 0.066845322 | J3: =IFERROR(LOOKUP(2,1/((Bank_Rates!$A$2:$A$100=H3)*(Bank_Rates!$B$2:$B$100=LOOKUP(2,1/((Bank_Rates!$A$2:$A$100=H3)*(Bank_Rates!$B$2:$B$100<=C3)),Bank_Rates!$B$2:$B$100))*(Bank_Rates!$D$2:$D$100<=G3)),Bank_Rates!$C$2:$C$100),"No Match") -> 0.04 | K3: =IF(OR(I3="",J3=""),"",I3-J3) -> 0.026845322
A4: =IF(B4<>"","L-"&TEXT(ROW()-1,"0000"),"") -> L-0003 | B4: TP03093 | C4: 46253 | D4: 4610986 | E4: 4626551 | F4: 46272 | G4: =RawObservationsTable[[#This Row],[Maturity Date]]-RawObservationsTable[[#This Row],[Timestamp]] -> 19 | H4: MBB | I4: =(RawObservationsTable[[#This Row],[Value at Maturity ($)]]/RawObservationsTable[[#This Row],[Price ($)]])^(365/RawObservationsTable[[#This Row],[Remaining Duration (Days)]])-1 -> 0.066879994 | J4: =IFERROR(LOOKUP(2,1/((Bank_Rates!$A$2:$A$100=H4)*(Bank_Rates!$B$2:$B$100=LOOKUP(2,1/((Bank_Rates!$A$2:$A$100=H4)*(Bank_Rates!$B$2:$B$100<=C4)),Bank_Rates!$B$2:$B$100))*(Bank_Rates!$D$2:$D$100<=G4)),Bank_Rates!$C$2:$C$100),"No Match") -> 0.04 | K4: =IF(OR(I4="",J4=""),"",I4-J4) -> 0.026879994
A5: =IF(B5<>"","L-"&TEXT(ROW()-1,"0000"),"") -> L-0004 | B5: TP03104 | C5: 46253 | D5: 3508456 | E5: 3520202 | F5: 46272 | G5: =RawObservationsTable[[#This Row],[Maturity Date]]-RawObservationsTable[[#This Row],[Timestamp]] -> 19 | H5: MBB | I5: =(RawObservationsTable[[#This Row],[Value at Maturity ($)]]/RawObservationsTable[[#This Row],[Price ($)]])^(365/RawObservationsTable[[#This Row],[Remaining Duration (Days)]])-1 -> 0.06631387 | J5: =IFERROR(LOOKUP(2,1/((Bank_Rates!$A$2:$A$100=H5)*(Bank_Rates!$B$2:$B$100=LOOKUP(2,1/((Bank_Rates!$A$2:$A$100=H5)*(Bank_Rates!$B$2:$B$100<=C5)),Bank_Rates!$B$2:$B$100))*(Bank_Rates!$D$2:$D$100<=G5)),Bank_Rates!$C$2:$C$100),"No Match") -> 0.04 | K5: =IF(OR(I5="",J5=""),"",I5-J5) -> 0.02631387
A6: =IF(B6<>"","L-"&TEXT(ROW()-1,"0000"),"") -> L-0005 | B6: TP00964 | C6: 46245 | D6: 6671860 | E6: 6749674 | F6: 46305 | G6: =RawObservationsTable[[#This Row],[Maturity Date]]-RawObservationsTable[[#This Row],[Timestamp]] -> 60 | H6: MBB | I6: =(RawObservationsTable[[#This Row],[Value at Maturity ($)]]/RawObservationsTable[[#This Row],[Price ($)]])^(365/RawObservationsTable[[#This Row],[Remaining Duration (Days)]])-1 -> 0.0730869 | J6: =IFERROR(LOOKUP(2,1/((Bank_Rates!$A$2:$A$100=H6)*(Bank_Rates!$B$2:$B$100=LOOKUP(2,1/((Bank_Rates!$A$2:$A$100=H6)*(Bank_Rates!$B$2:$B$100<=C6)),Bank_Rates!$B$2:$B$100))*(Bank_Rates!$D$2:$D$100<=G6)),Bank_Rates!$C$2:$C$100),"No Match") -> 0.067 | K6: =IF(OR(I6="",J6=""),"",I6-J6) -> 0.0060869004
A7: =IF(B7<>"","L-"&TEXT(ROW()-1,"0000"),"") -> L-0006 | B7: TP03429 | C7: 46247 | D7: 20060000 | E7: 20826744 | F7: 46430 | G7: =RawObservationsTable[[#This Row],[Maturity Date]]-RawObservationsTable[[#This Row],[Timestamp]] -> 183 | H7: MBB | I7: =(RawObservationsTable[[#This Row],[Value at Maturity ($)]]/RawObservationsTable[[#This Row],[Price ($)]])^(365/RawObservationsTable[[#This Row],[Remaining Duration (Days)]])-1 -> 0.077685107 | J7: =IFERROR(LOOKUP(2,1/((Bank_Rates!$A$2:$A$100=H7)*(Bank_Rates!$B$2:$B$100=LOOKUP(2,1/((Bank_Rates!$A$2:$A$100=H7)*(Bank_Rates!$B$2:$B$100<=C7)),Bank_Rates!$B$2:$B$100))*(Bank_Rates!$D$2:$D$100<=G7)),Bank_Rates!$C$2:$C$100),"No Match") -> 0.071 | K7: =IF(OR(I7="",J7=""),"",I7-J7) -> 0.0066851073
A8: =IF(B8<>"","L-"&TEXT(ROW()-1,"0000"),"") -> L-0007 | B8: TP00537 | C8: 46248 | D8: 29685213 | E8: 30297331 | F8: 46346 | G8: =RawObservationsTable[[#This Row],[Maturity Date]]-RawObservationsTable[[#This Row],[Timestamp]] -> 98 | H8: MBB | I8: =(RawObservationsTable[[#This Row],[Value at Maturity ($)]]/RawObservationsTable[[#This Row],[Price ($)]])^(365/RawObservationsTable[[#This Row],[Remaining Duration (Days)]])-1 -> 0.07898307 | J8: =IFERROR(LOOKUP(2,1/((Bank_Rates!$A$2:$A$100=H8)*(Bank_Rates!$B$2:$B$100=LOOKUP(2,1/((Bank_Rates!$A$2:$A$100=H8)*(Bank_Rates!$B$2:$B$100<=C8)),Bank_Rates!$B$2:$B$100))*(Bank_Rates!$D$2:$D$100<=G8)),Bank_Rates!$C$2:$C$100),"No Match") -> 0.07 | K8: =IF(OR(I8="",J8=""),"",I8-J8) -> 0.0089830705
A9: =IF(B9<>"","L-"&TEXT(ROW()-1,"0000"),"") -> L-0008 | B9: TP01034 | C9: 46248 | D9: 30046000 | E9: 31206091 | F9: 46431 | G9: =RawObservationsTable[[#This Row],[Maturity Date]]-RawObservationsTable[[#This Row],[Timestamp]] -> 183 | H9: MBB | I9: =(RawObservationsTable[[#This Row],[Value at Maturity ($)]]/RawObservationsTable[[#This Row],[Price ($)]])^(365/RawObservationsTable[[#This Row],[Remaining Duration (Days)]])-1 -> 0.078488478 | J9: =IFERROR(LOOKUP(2,1/((Bank_Rates!$A$2:$A$100=H9)*(Bank_Rates!$B$2:$B$100=LOOKUP(2,1/((Bank_Rates!$A$2:$A$100=H9)*(Bank_Rates!$B$2:$B$100<=C9)),Bank_Rates!$B$2:$B$100))*(Bank_Rates!$D$2:$D$100<=G9)),Bank_Rates!$C$2:$C$100),"No Match") -> 0.071 | K9: =IF(OR(I9="",J9=""),"",I9-J9) -> 0.0074884785
A10: =IF(B10<>"","L-"&TEXT(ROW()-1,"0000"),"") -> L-0009 | B10: TP00945 | C10: 46251 | D10: 20064000 | E10: 20110411 | F10: 46264 | G10: =RawObservationsTable[[#This Row],[Maturity Date]]-RawObservationsTable[[#This Row],[Timestamp]] -> 13 | H10: MBB | I10: =(RawObservationsTable[[#This Row],[Value at Maturity ($)]]/RawObservationsTable[[#This Row],[Price ($)]])^(365/RawObservationsTable[[#This Row],[Remaining Duration (Days)]])-1 -> 0.067021452 | J10: =IFERROR(LOOKUP(2,1/((Bank_Rates!$A$2:$A$100=H10)*(Bank_Rates!$B$2:$B$100=LOOKUP(2,1/((Bank_Rates!$A$2:$A$100=H10)*(Bank_Rates!$B$2:$B$100<=C10)),Bank_Rates!$B$2:$B$100))*(Bank_Rates!$D$2:$D$100<=G10)),Bank_Rates!$C$2:$C$100),"No Match") -> 0.04 | K10: =IF(OR(I10="",J10=""),"",I10-J10) -> 0.027021452
A11: =IF(B11<>"","L-"&TEXT(ROW()-1,"0000"),"") -> L-0010 | B11: TP00558 | C11: 46256 | D11: 50217550 | E11: 50305612 | F11: 46266 | G11: =RawObservationsTable[[#This Row],[Maturity Date]]-RawObservationsTable[[#This Row],[Timestamp]] -> 10 | H11: MBB | I11: =(RawObservationsTable[[#This Row],[Value at Maturity ($)]]/RawObservationsTable[[#This Row],[Price ($)]])^(365/RawObservationsTable[[#This Row],[Remaining Duration (Days)]])-1 -> 0.066039853 | J11: =IFERROR(LOOKUP(2,1/((Bank_Rates!$A$2:$A$100=H11)*(Bank_Rates!$B$2:$B$100=LOOKUP(2,1/((Bank_Rates!$A$2:$A$100=H11)*(Bank_Rates!$B$2:$B$100<=C11)),Bank_Rates!$B$2:$B$100))*(Bank_Rates!$D$2:$D$100<=G11)),Bank_Rates!$C$2:$C$100),"No Match") -> 0.04 | K11: =IF(OR(I11="",J11=""),"",I11-J11) -> 0.026039853
A12: =IF(B12<>"","L-"&TEXT(ROW()-1,"0000"),"") -> L-0011 | B12: TP00877 | C12: 46256 | D12: 9927097 | E12: 9963029 | F12: 46276 | G12: =RawObservationsTable[[#This Row],[Maturity Date]]-RawObservationsTable[[#This Row],[Timestamp]] -> 20 | H12: MBB | I12: =(RawObservationsTable[[#This Row],[Value at Maturity ($)]]/RawObservationsTable[[#This Row],[Price ($)]])^(365/RawObservationsTable[[#This Row],[Remaining Duration (Days)]])-1 -> 0.06816072 | J12: =IFERROR(LOOKUP(2,1/((Bank_Rates!$A$2:$A$100=H12)*(Bank_Rates!$B$2:$B$100=LOOKUP(2,1/((Bank_Rates!$A$2:$A$100=H12)*(Bank_Rates!$B$2:$B$100<=C12)),Bank_Rates!$B$2:$B$100))*(Bank_Rates!$D$2:$D$100<=G12)),Bank_Rates!$C$2:$C$100),"No Match") -> 0.04 | K12: =IF(OR(I12="",J12=""),"",I12-J12) -> 0.02816072
A13: =IF(B13<>"","L-"&TEXT(ROW()-1,"0000"),"") -> L-0012 | B13: TP01801 | C13: 46256 | D13: 6557889 | E13: 6584707 | F13: 46269 | G13: =RawObservationsTable[[#This Row],[Maturity Date]]-RawObservationsTable[[#This Row],[Timestamp]] -> 13 | H13: MBB | I13: =(RawObservationsTable[[#This Row],[Value at Maturity ($)]]/RawObservationsTable[[#This Row],[Price ($)]])^(365/RawObservationsTable[[#This Row],[Remaining Duration (Days)]])-1 -> 0.12140724 | J13: =IFERROR(LOOKUP(2,1/((Bank_Rates!$A$2:$A$100=H13)*(Bank_Rates!$B$2:$B$100=LOOKUP(2,1/((Bank_Rates!$A$2:$A$100=H13)*(Bank_Rates!$B$2:$B$100<=C13)),Bank_Rates!$B$2:$B$100))*(Bank_Rates!$D$2:$D$100<=G13)),Bank_Rates!$C$2:$C$100),"No Match") -> 0.04 | K13: =IF(OR(I13="",J13=""),"",I13-J13) -> 0.081407238
... A15: =IF(B15<>"","L-"&TEXT(ROW()-1,"0000"),"") -> L-0014 | B15: TP93098 | C15: 46256 | D15: 49969000 | E15: 51993393 | F15: 46439 | G15: =RawObservationsTable[[#This Row],[Maturity Date]]-RawObservationsTable[[#This Row],[Timestamp]] -> 183 | H15: MBB | I15: =(RawObservationsTable[[#This Row],[Value at Maturity ($)]]/RawObservationsTable[[#This Row],[Price ($)]])^(365/RawObservationsTable[[#This Row],[Remaining Duration (Days)]])-1 -> 0.082432327 | J15: =IFERROR(LOOKUP(2,1/((Bank_Rates!$A$2:$A$100=H15)*(Bank_Rates!$B$2:$B$100=LOOKUP(2,1/((Bank_Rates!$A$2:$A$100=H15)*(Bank_Rates!$B$2:$B$100<=C15)),Bank_Rates!$B$2:$B$100))*(Bank_Rates!$D$2:$D$100<=G15)),Bank_Rates!$C$2:$C$100),"No Match") -> 0.071 | K15: =IF(OR(I15="",J15=""),"",I15-J15) -> 0.011432327
A16: =IF(B16<>"","L-"&TEXT(ROW()-1,"0000"),"") | G16: =RawObservationsTable[[#This Row],[Maturity Date]]-RawObservationsTable[[#This Row],[Timestamp]] -> 0 | J16: =IFERROR(LOOKUP(2,1/((Bank_Rates!$A$2:$A$100=H16)*(Bank_Rates!$B$2:$B$100=LOOKUP(2,1/((Bank_Rates!$A$2:$A$100=H16)*(Bank_Rates!$B$2:$B$100<=C16)),Bank_Rates!$B$2:$B$100))*(Bank_Rates!$D$2:$D$100<=G16)),Bank_Rates!$C$2:$C$100),"No Match") -> 0 | K16: =IF(OR(I16="",J16=""),"",I16-J16)
A17: =IF(B17<>"","L-"&TEXT(ROW()-1,"0000"),"") | G17: =RawObservationsTable[[#This Row],[Maturity Date]]-RawObservationsTable[[#This Row],[Timestamp]] -> 0 | J17: =IFERROR(LOOKUP(2,1/((Bank_Rates!$A$2:$A$100=H17)*(Bank_Rates!$B$2:$B$100=LOOKUP(2,1/((Bank_Rates!$A$2:$A$100=H17)*(Bank_Rates!$B$2:$B$100<=C17)),Bank_Rates!$B$2:$B$100))*(Bank_Rates!$D$2:$D$100<=G17)),Bank_Rates!$C$2:$C$100),"No Match") -> 0 | K17: =IF(OR(I17="",J17=""),"",I17-J17)
A18: =IF(B18<>"","L-"&TEXT(ROW()-1,"0000"),"") | G18: =RawObservationsTable[[#This Row],[Maturity Date]]-RawObservationsTable[[#This Row],[Timestamp]] -> 0 | J18: =IFERROR(LOOKUP(2,1/((Bank_Rates!$A$2:$A$100=H18)*(Bank_Rates!$B$2:$B$100=LOOKUP(2,1/((Bank_Rates!$A$2:$A$100=H18)*(Bank_Rates!$B$2:$B$100<=C18)),Bank_Rates!$B$2:$B$100))*(Bank_Rates!$D$2:$D$100<=G18)),Bank_Rates!$C$2:$C$100),"No Match") -> 0 | K18: =IF(OR(I18="",J18=""),"",I18-J18)
A19: =IF(B19<>"","L-"&TEXT(ROW()-1,"0000"),"") | G19: =RawObservationsTable[[#This Row],[Maturity Date]]-RawObservationsTable[[#This Row],[Timestamp]] -> 0 | J19: =IFERROR(LOOKUP(2,1/((Bank_Rates!$A$2:$A$100=H19)*(Bank_Rates!$B$2:$B$100=LOOKUP(2,1/((Bank_Rates!$A$2:$A$100=H19)*(Bank_Rates!$B$2:$B$100<=C19)),Bank_Rates!$B$2:$B$100))*(Bank_Rates!$D$2:$D$100<=G19)),Bank_Rates!$C$2:$C$100),"No Match") -> 0 | K19: =IF(OR(I19="",J19=""),"",I19-J19)
A20: =IF(B20<>"","L-"&TEXT(ROW()-1,"0000"),"") | G20: =RawObservationsTable[[#This Row],[Maturity Date]]-RawObservationsTable[[#This Row],[Timestamp]] -> 0 | J20: =IFERROR(LOOKUP(2,1/((Bank_Rates!$A$2:$A$100=H20)*(Bank_Rates!$B$2:$B$100=LOOKUP(2,1/((Bank_Rates!$A$2:$A$100=H20)*(Bank_Rates!$B$2:$B$100<=C20)),Bank_Rates!$B$2:$B$100))*(Bank_Rates!$D$2:$D$100<=G20)),Bank_Rates!$C$2:$C$100),"No Match") -> 0 | K20: =IF(OR(I20="",J20=""),"",I20-J20)
A21: =IF(B21<>"","L-"&TEXT(ROW()-1,"0000"),"") | G21: =RawObservationsTable[[#This Row],[Maturity Date]]-RawObservationsTable[[#This Row],[Timestamp]] -> 0 | J21: =IFERROR(LOOKUP(2,1/((Bank_Rates!$A$2:$A$100=H21)*(Bank_Rates!$B$2:$B$100=LOOKUP(2,1/((Bank_Rates!$A$2:$A$100=H21)*(Bank_Rates!$B$2:$B$100<=C21)),Bank_Rates!$B$2:$B$100))*(Bank_Rates!$D$2:$D$100<=G21)),Bank_Rates!$C$2:$C$100),"No Match") -> 0 | K21: =IF(OR(I21="",J21=""),"",I21-J21)
A22: =IF(B22<>"","L-"&TEXT(ROW()-1,"0000"),"") | G22: =RawObservationsTable[[#This Row],[Maturity Date]]-RawObservationsTable[[#This Row],[Timestamp]] -> 0 | J22: =IFERROR(LOOKUP(2,1/((Bank_Rates!$A$2:$A$100=H22)*(Bank_Rates!$B$2:$B$100=LOOKUP(2,1/((Bank_Rates!$A$2:$A$100=H22)*(Bank_Rates!$B$2:$B$100<=C22)),Bank_Rates!$B$2:$B$100))*(Bank_Rates!$D$2:$D$100<=G22)),Bank_Rates!$C$2:$C$100),"No Match") -> 0 | K22: =IF(OR(I22="",J22=""),"",I22-J22)
A23: =IF(B23<>"","L-"&TEXT(ROW()-1,"0000"),"") | G23: =RawObservationsTable[[#This Row],[Maturity Date]]-RawObservationsTable[[#This Row],[Timestamp]] -> 0 | J23: =IFERROR(LOOKUP(2,1/((Bank_Rates!$A$2:$A$100=H23)*(Bank_Rates!$B$2:$B$100=LOOKUP(2,1/((Bank_Rates!$A$2:$A$100=H23)*(Bank_Rates!$B$2:$B$100<=C23)),Bank_Rates!$B$2:$B$100))*(Bank_Rates!$D$2:$D$100<=G23)),Bank_Rates!$C$2:$C$100),"No Match") -> 0 | K23: =IF(OR(I23="",J23=""),"",I23-J23)
A24: =IF(B24<>"","L-"&TEXT(ROW()-1,"0000"),"") | G24: =RawObservationsTable[[#This Row],[Maturity Date]]-RawObservationsTable[[#This Row],[Timestamp]] -> 0 | J24: =IFERROR(LOOKUP(2,1/((Bank_Rates!$A$2:$A$100=H24)*(Bank_Rates!$B$2:$B$100=LOOKUP(2,1/((Bank_Rates!$A$2:$A$100=H24)*(Bank_Rates!$B$2:$B$100<=C24)),Bank_Rates!$B$2:$B$100))*(Bank_Rates!$D$2:$D$100<=G24)),Bank_Rates!$C$2:$C$100),"No Match") -> 0 | K24: =IF(OR(I24="",J24=""),"",I24-J24)
A25: =IF(B25<>"","L-"&TEXT(ROW()-1,"0000"),"") | G25: =RawObservationsTable[[#This Row],[Maturity Date]]-RawObservationsTable[[#This Row],[Timestamp]] -> 0 | J25: =IFERROR(LOOKUP(2,1/((Bank_Rates!$A$2:$A$100=H25)*(Bank_Rates!$B$2:$B$100=LOOKUP(2,1/((Bank_Rates!$A$2:$A$100=H25)*(Bank_Rates!$B$2:$B$100<=C25)),Bank_Rates!$B$2:$B$100))*(Bank_Rates!$D$2:$D$100<=G25)),Bank_Rates!$C$2:$C$100),"No Match") -> 0 | K25: =IF(OR(I25="",J25=""),"",I25-J25)
A26: =IF(B26<>"","L-"&TEXT(ROW()-1,"0000"),"") | G26: =RawObservationsTable[[#This Row],[Maturity Date]]-RawObservationsTable[[#This Row],[Timestamp]] -> 0 | J26: =IFERROR(LOOKUP(2,1/((Bank_Rates!$A$2:$A$100=H26)*(Bank_Rates!$B$2:$B$100=LOOKUP(2,1/((Bank_Rates!$A$2:$A$100=H26)*(Bank_Rates!$B$2:$B$100<=C26)),Bank_Rates!$B$2:$B$100))*(Bank_Rates!$D$2:$D$100<=G26)),Bank_Rates!$C$2:$C$100),"No Match") -> 0 | K26: =IF(OR(I26="",J26=""),"",I26-J26)
A27: =IF(B27<>"","L-"&TEXT(ROW()-1,"0000"),"") | G27: =RawObservationsTable[[#This Row],[Maturity Date]]-RawObservationsTable[[#This Row],[Timestamp]] -> 0 | J27: =IFERROR(LOOKUP(2,1/((Bank_Rates!$A$2:$A$100=H27)*(Bank_Rates!$B$2:$B$100=LOOKUP(2,1/((Bank_Rates!$A$2:$A$100=H27)*(Bank_Rates!$B$2:$B$100<=C27)),Bank_Rates!$B$2:$B$100))*(Bank_Rates!$D$2:$D$100<=G27)),Bank_Rates!$C$2:$C$100),"No Match") -> 0 | K27: =IF(OR(I27="",J27=""),"",I27-J27)
A28: =IF(B28<>"","L-"&TEXT(ROW()-1,"0000"),"") | G28: =RawObservationsTable[[#This Row],[Maturity Date]]-RawObservationsTable[[#This Row],[Timestamp]] -> 0 | J28: =IF(OR(H28="",G28="",C28=""),"",LET(n,COUNTIFS(Bank_Rates!$A$2:$A$501,H28,Bank_Rates!$B$2:$B$501,"<="&C28),IF(n=0,"",LET(t,MAXIFS(Bank_Rates!$B$2:$B$501,Bank_Rates!$A$2:$A$501,H28,Bank_Rates!$B$2:$B$501,"<="&C28),m,COUNTIFS(Bank_Rates!$A$2:$A$501,H28,Bank_Rates!$B$2:$B$501,t,Bank_Rates!$D$2:$D$501,"<="&G28),IF(m=0,"",LET(d,MAXIFS(Bank_Rates!$D$2:$D$501,Bank_Rates!$A$2:$A$501,H28,Bank_Rates!$B$2:$B$501,t,Bank_Rates!$D$2:$D$501,"<="&G28),SUMIFS(Bank_Rates!$C$2:$C$501,Bank_Rates!$A$2:$A$501,H28,Bank_Rates!$B$2:$B$501,t,Bank_Rates!$D$2:$D$501,d))))))) | K28: =IF(OR(I28="",J28=""),"",I28-J28)
A29: =IF(B29<>"","L-"&TEXT(ROW()-1,"0000"),"") | G29: =RawObservationsTable[[#This Row],[Maturity Date]]-RawObservationsTable[[#This Row],[Timestamp]] -> 0 | J29: =IF(OR(H29="",G29="",C29=""),"",LET(n,COUNTIFS(Bank_Rates!$A$2:$A$501,H29,Bank_Rates!$B$2:$B$501,"<="&C29),IF(n=0,"",LET(t,MAXIFS(Bank_Rates!$B$2:$B$501,Bank_Rates!$A$2:$A$501,H29,Bank_Rates!$B$2:$B$501,"<="&C29),m,COUNTIFS(Bank_Rates!$A$2:$A$501,H29,Bank_Rates!$B$2:$B$501,t,Bank_Rates!$D$2:$D$501,"<="&G29),IF(m=0,"",LET(d,MAXIFS(Bank_Rates!$D$2:$D$501,Bank_Rates!$A$2:$A$501,H29,Bank_Rates!$B$2:$B$501,t,Bank_Rates!$D$2:$D$501,"<="&G29),SUMIFS(Bank_Rates!$C$2:$C$501,Bank_Rates!$A$2:$A$501,H29,Bank_Rates!$B$2:$B$501,t,Bank_Rates!$D$2:$D$501,d))))))) | K29: =IF(OR(I29="",J29=""),"",I29-J29)
A30: =IF(B30<>"","L-"&TEXT(ROW()-1,"0000"),"") | G30: =RawObservationsTable[[#This Row],[Maturity Date]]-RawObservationsTable[[#This Row],[Timestamp]] -> 0 | J30: =IF(OR(H30="",G30="",C30=""),"",LET(n,COUNTIFS(Bank_Rates!$A$2:$A$501,H30,Bank_Rates!$B$2:$B$501,"<="&C30),IF(n=0,"",LET(t,MAXIFS(Bank_Rates!$B$2:$B$501,Bank_Rates!$A$2:$A$501,H30,Bank_Rates!$B$2:$B$501,"<="&C30),m,COUNTIFS(Bank_Rates!$A$2:$A$501,H30,Bank_Rates!$B$2:$B$501,t,Bank_Rates!$D$2:$D$501,"<="&G30),IF(m=0,"",LET(d,MAXIFS(Bank_Rates!$D$2:$D$501,Bank_Rates!$A$2:$A$501,H30,Bank_Rates!$B$2:$B$501,t,Bank_Rates!$D$2:$D$501,"<="&G30),SUMIFS(Bank_Rates!$C$2:$C$501,Bank_Rates!$A$2:$A$501,H30,Bank_Rates!$B$2:$B$501,t,Bank_Rates!$D$2:$D$501,d))))))) | K30: =IF(OR(I30="",J30=""),"",I30-J30)
A31: =IF(B31<>"","L-"&TEXT(ROW()-1,"0000"),"") | G31: =RawObservationsTable[[#This Row],[Maturity Date]]-RawObservationsTable[[#This Row],[Timestamp]] -> 0 | J31: =IF(OR(H31="",G31="",C31=""),"",LET(n,COUNTIFS(Bank_Rates!$A$2:$A$501,H31,Bank_Rates!$B$2:$B$501,"<="&C31),IF(n=0,"",LET(t,MAXIFS(Bank_Rates!$B$2:$B$501,Bank_Rates!$A$2:$A$501,H31,Bank_Rates!$B$2:$B$501,"<="&C31),m,COUNTIFS(Bank_Rates!$A$2:$A$501,H31,Bank_Rates!$B$2:$B$501,t,Bank_Rates!$D$2:$D$501,"<="&G31),IF(m=0,"",LET(d,MAXIFS(Bank_Rates!$D$2:$D$501,Bank_Rates!$A$2:$A$501,H31,Bank_Rates!$B$2:$B$501,t,Bank_Rates!$D$2:$D$501,"<="&G31),SUMIFS(Bank_Rates!$C$2:$C$501,Bank_Rates!$A$2:$A$501,H31,Bank_Rates!$B$2:$B$501,t,Bank_Rates!$D$2:$D$501,d))))))) | K31: =IF(OR(I31="",J31=""),"",I31-J31)
A32: =IF(B32<>"","L-"&TEXT(ROW()-1,"0000"),"") | G32: =RawObservationsTable[[#This Row],[Maturity Date]]-RawObservationsTable[[#This Row],[Timestamp]] -> 0 | J32: =IF(OR(H32="",G32="",C32=""),"",LET(n,COUNTIFS(Bank_Rates!$A$2:$A$501,H32,Bank_Rates!$B$2:$B$501,"<="&C32),IF(n=0,"",LET(t,MAXIFS(Bank_Rates!$B$2:$B$501,Bank_Rates!$A$2:$A$501,H32,Bank_Rates!$B$2:$B$501,"<="&C32),m,COUNTIFS(Bank_Rates!$A$2:$A$501,H32,Bank_Rates!$B$2:$B$501,t,Bank_Rates!$D$2:$D$501,"<="&G32),IF(m=0,"",LET(d,MAXIFS(Bank_Rates!$D$2:$D$501,Bank_Rates!$A$2:$A$501,H32,Bank_Rates!$B$2:$B$501,t,Bank_Rates!$D$2:$D$501,"<="&G32),SUMIFS(Bank_Rates!$C$2:$C$501,Bank_Rates!$A$2:$A$501,H32,Bank_Rates!$B$2:$B$501,t,Bank_Rates!$D$2:$D$501,d))))))) | K32: =IF(OR(I32="",J32=""),"",I32-J32)
A33: =IF(B33<>"","L-"&TEXT(ROW()-1,"0000"),"") | G33: =RawObservationsTable[[#This Row],[Maturity Date]]-RawObservationsTable[[#This Row],[Timestamp]] -> 0 | J33: =IF(OR(H33="",G33="",C33=""),"",LET(n,COUNTIFS(Bank_Rates!$A$2:$A$501,H33,Bank_Rates!$B$2:$B$501,"<="&C33),IF(n=0,"",LET(t,MAXIFS(Bank_Rates!$B$2:$B$501,Bank_Rates!$A$2:$A$501,H33,Bank_Rates!$B$2:$B$501,"<="&C33),m,COUNTIFS(Bank_Rates!$A$2:$A$501,H33,Bank_Rates!$B$2:$B$501,t,Bank_Rates!$D$2:$D$501,"<="&G33),IF(m=0,"",LET(d,MAXIFS(Bank_Rates!$D$2:$D$501,Bank_Rates!$A$2:$A$501,H33,Bank_Rates!$B$2:$B$501,t,Bank_Rates!$D$2:$D$501,"<="&G33),SUMIFS(Bank_Rates!$C$2:$C$501,Bank_Rates!$A$2:$A$501,H33,Bank_Rates!$B$2:$B$501,t,Bank_Rates!$D$2:$D$501,d))))))) | K33: =IF(OR(I33="",J33=""),"",I33-J33)
A34: =IF(B34<>"","L-"&TEXT(ROW()-1,"0000"),"") | G34: =RawObservationsTable[[#This Row],[Maturity Date]]-RawObservationsTable[[#This Row],[Timestamp]] -> 0 | J34: =IF(OR(H34="",G34="",C34=""),"",LET(n,COUNTIFS(Bank_Rates!$A$2:$A$501,H34,Bank_Rates!$B$2:$B$501,"<="&C34),IF(n=0,"",LET(t,MAXIFS(Bank_Rates!$B$2:$B$501,Bank_Rates!$A$2:$A$501,H34,Bank_Rates!$B$2:$B$501,"<="&C34),m,COUNTIFS(Bank_Rates!$A$2:$A$501,H34,Bank_Rates!$B$2:$B$501,t,Bank_Rates!$D$2:$D$501,"<="&G34),IF(m=0,"",LET(d,MAXIFS(Bank_Rates!$D$2:$D$501,Bank_Rates!$A$2:$A$501,H34,Bank_Rates!$B$2:$B$501,t,Bank_Rates!$D$2:$D$501,"<="&G34),SUMIFS(Bank_Rates!$C$2:$C$501,Bank_Rates!$A$2:$A$501,H34,Bank_Rates!$B$2:$B$501,t,Bank_Rates!$D$2:$D$501,d))))))) | K34: =IF(OR(I34="",J34=""),"",I34-J34)
A35: =IF(B35<>"","L-"&TEXT(ROW()-1,"0000"),"") | G35: =RawObservationsTable[[#This Row],[Maturity Date]]-RawObservationsTable[[#This Row],[Timestamp]] -> 0 | J35: =IF(OR(H35="",G35="",C35=""),"",LET(n,COUNTIFS(Bank_Rates!$A$2:$A$501,H35,Bank_Rates!$B$2:$B$501,"<="&C35),IF(n=0,"",LET(t,MAXIFS(Bank_Rates!$B$2:$B$501,Bank_Rates!$A$2:$A$501,H35,Bank_Rates!$B$2:$B$501,"<="&C35),m,COUNTIFS(Bank_Rates!$A$2:$A$501,H35,Bank_Rates!$B$2:$B$501,t,Bank_Rates!$D$2:$D$501,"<="&G35),IF(m=0,"",LET(d,MAXIFS(Bank_Rates!$D$2:$D$501,Bank_Rates!$A$2:$A$501,H35,Bank_Rates!$B$2:$B$501,t,Bank_Rates!$D$2:$D$501,"<="&G35),SUMIFS(Bank_Rates!$C$2:$C$501,Bank_Rates!$A$2:$A$501,H35,Bank_Rates!$B$2:$B$501,t,Bank_Rates!$D$2:$D$501,d))))))) | K35: =IF(OR(I35="",J35=""),"",I35-J35)
A36: =IF(B36<>"","L-"&TEXT(ROW()-1,"0000"),"") | G36: =RawObservationsTable[[#This Row],[Maturity Date]]-RawObservationsTable[[#This Row],[Timestamp]] -> 0 | J36: =IF(OR(H36="",G36="",C36=""),"",LET(n,COUNTIFS(Bank_Rates!$A$2:$A$501,H36,Bank_Rates!$B$2:$B$501,"<="&C36),IF(n=0,"",LET(t,MAXIFS(Bank_Rates!$B$2:$B$501,Bank_Rates!$A$2:$A$501,H36,Bank_Rates!$B$2:$B$501,"<="&C36),m,COUNTIFS(Bank_Rates!$A$2:$A$501,H36,Bank_Rates!$B$2:$B$501,t,Bank_Rates!$D$2:$D$501,"<="&G36),IF(m=0,"",LET(d,MAXIFS(Bank_Rates!$D$2:$D$501,Bank_Rates!$A$2:$A$501,H36,Bank_Rates!$B$2:$B$501,t,Bank_Rates!$D$2:$D$501,"<="&G36),SUMIFS(Bank_Rates!$C$2:$C$501,Bank_Rates!$A$2:$A$501,H36,Bank_Rates!$B$2:$B$501,t,Bank_Rates!$D$2:$D$501,d))))))) | K36: =IF(OR(I36="",J36=""),"",I36-J36)
A37: =IF(B37<>"","L-"&TEXT(ROW()-1,"0000"),"") | G37: =RawObservationsTable[[#This Row],[Maturity Date]]-RawObservationsTable[[#This Row],[Timestamp]] -> 0 | J37: =IF(OR(H37="",G37="",C37=""),"",LET(n,COUNTIFS(Bank_Rates!$A$2:$A$501,H37,Bank_Rates!$B$2:$B$501,"<="&C37),IF(n=0,"",LET(t,MAXIFS(Bank_Rates!$B$2:$B$501,Bank_Rates!$A$2:$A$501,H37,Bank_Rates!$B$2:$B$501,"<="&C37),m,COUNTIFS(Bank_Rates!$A$2:$A$501,H37,Bank_Rates!$B$2:$B$501,t,Bank_Rates!$D$2:$D$501,"<="&G37),IF(m=0,"",LET(d,MAXIFS(Bank_Rates!$D$2:$D$501,Bank_Rates!$A$2:$A$501,H37,Bank_Rates!$B$2:$B$501,t,Bank_Rates!$D$2:$D$501,"<="&G37),SUMIFS(Bank_Rates!$C$2:$C$501,Bank_Rates!$A$2:$A$501,H37,Bank_Rates!$B$2:$B$501,t,Bank_Rates!$D$2:$D$501,d))))))) | K37: =IF(OR(I37="",J37=""),"",I37-J37)
A38: =IF(B38<>"","L-"&TEXT(ROW()-1,"0000"),"") | G38: =RawObservationsTable[[#This Row],[Maturity Date]]-RawObservationsTable[[#This Row],[Timestamp]] -> 0 | J38: =IF(OR(H38="",G38="",C38=""),"",LET(n,COUNTIFS(Bank_Rates!$A$2:$A$501,H38,Bank_Rates!$B$2:$B$501,"<="&C38),IF(n=0,"",LET(t,MAXIFS(Bank_Rates!$B$2:$B$501,Bank_Rates!$A$2:$A$501,H38,Bank_Rates!$B$2:$B$501,"<="&C38),m,COUNTIFS(Bank_Rates!$A$2:$A$501,H38,Bank_Rates!$B$2:$B$501,t,Bank_Rates!$D$2:$D$501,"<="&G38),IF(m=0,"",LET(d,MAXIFS(Bank_Rates!$D$2:$D$501,Bank_Rates!$A$2:$A$501,H38,Bank_Rates!$B$2:$B$501,t,Bank_Rates!$D$2:$D$501,"<="&G38),SUMIFS(Bank_Rates!$C$2:$C$501,Bank_Rates!$A$2:$A$501,H38,Bank_Rates!$B$2:$B$501,t,Bank_Rates!$D$2:$D$501,d))))))) | K38: =IF(OR(I38="",J38=""),"",I38-J38)
A39: =IF(B39<>"","L-"&TEXT(ROW()-1,"0000"),"") | G39: =RawObservationsTable[[#This Row],[Maturity Date]]-RawObservationsTable[[#This Row],[Timestamp]] -> 0 | J39: =IF(OR(H39="",G39="",C39=""),"",LET(n,COUNTIFS(Bank_Rates!$A$2:$A$501,H39,Bank_Rates!$B$2:$B$501,"<="&C39),IF(n=0,"",LET(t,MAXIFS(Bank_Rates!$B$2:$B$501,Bank_Rates!$A$2:$A$501,H39,Bank_Rates!$B$2:$B$501,"<="&C39),m,COUNTIFS(Bank_Rates!$A$2:$A$501,H39,Bank_Rates!$B$2:$B$501,t,Bank_Rates!$D$2:$D$501,"<="&G39),IF(m=0,"",LET(d,MAXIFS(Bank_Rates!$D$2:$D$501,Bank_Rates!$A$2:$A$501,H39,Bank_Rates!$B$2:$B$501,t,Bank_Rates!$D$2:$D$501,"<="&G39),SUMIFS(Bank_Rates!$C$2:$C$501,Bank_Rates!$A$2:$A$501,H39,Bank_Rates!$B$2:$B$501,t,Bank_Rates!$D$2:$D$501,d))))))) | K39: =IF(OR(I39="",J39=""),"",I39-J39)
... A1001: =IF(B1001<>"","L-"&TEXT(ROW()-1,"0000"),"") | G1001: =RawObservationsTable[[#This Row],[Maturity Date]]-RawObservationsTable[[#This Row],[Timestamp]] -> 0 | J1001: =IF(OR(H1001="",G1001="",C1001=""),"",LET(n,COUNTIFS(Bank_Rates!$A$2:$A$501,H1001,Bank_Rates!$B$2:$B$501,"<="&C1001),IF(n=0,"",LET(t,MAXIFS(Bank_Rates!$B$2:$B$501,Bank_Rates!$A$2:$A$501,H1001,Bank_Rates!$B$2:$B$501,"<="&C1001),m,COUNTIFS(Bank_Rates!$A$2:$A$501,H1001,Bank_Rates!$B$2:$B$501,t,Bank_Rates!$D$2:$D$501,"<="&G1001),IF(m=0,"",LET(d,MAXIFS(Bank_Rates!$D$2:$D$501,Bank_Rates!$A$2:$A$501,H1001,Bank_Rates!$B$2:$B$501,t,Bank_Rates!$D$2:$D$501,"<="&G1001),SUMIFS(Bank_Rates!$C$2:$C$501,Bank_Rates!$A$2:$A$501,H1001,Bank_Rates!$B$2:$B$501,t,Bank_Rates!$D$2:$D$501,d))))))) | K1001: =IF(OR(I1001="",J1001=""),"",I1001-J1001)

Sheet Pricing
A1: Listing ID | B1: CD ID | C1: Value at Maturity ($) | D1: Remaining Days | E1: Corresponding Rate | F1: Entry Spread | G1: Liquidity Spread | H1: Pricing Yield | I1: Model Price ($)
A2: L-0001 | B2: TP03077 | C2: {=INDEX(Raw_Observations!$E$2:$E$1000,MATCH(1,(Raw_Observations!$A$2:$A$1000=A2)*(Raw_Observations!$B$2:$B$1000=B2),0))} -> 4671001 | D2: =MAX(IF(COUNTIFS(Raw_Observations!$A:$A,A2,Raw_Observations!$B:$B,B2)=0,"",SUMIFS(Raw_Observations!$F:$F,Raw_Observations!$A:$A,A2,Raw_Observations!$B:$B,B2)-TODAY()),0) -> 17 | E2: =IFERROR(LOOKUP(2,1/((Bank_Rates!$A$2:$A$100=LOOKUP(2,1/((Raw_Observations!$A$2:$A$1000=A2)*(Raw_Observations!$B$2:$B$1000=B2)),Raw_Observations!$H$2:$H$1000))*(Bank_Rates!$B$2:$B$100=LOOKUP(2,1/((Bank_Rates!$A$2:$A$100=LOOKUP(2,1/((Raw_Observations!$A$2:$A$1000=A2)*(Raw_Observations!$B$2:$B$1000=B2)),Raw_Observations!$H$2:$H$1000))*(Bank_Rates!$B$2:$B$100<=TODAY())),Bank_Rates!$B$2:$B$100))*(Bank_Rates!$D$2:$D$100<=D2)),Bank_Rates!$C$2:$C$100),"No Match") -> 0.04 | F2: {=INDEX(Raw_Observations!$K$2:$K$1000,MATCH(1,(Raw_Observations!$A$2:$A$1000=A2)*(Raw_Observations!$B$2:$B$1000=B2),0))} -> 0.026869531 | G2: 0.02 | H2: =E2+G2 -> 0.06 | I2: =C2/((1+E2+G2)^(D2/365)) -> 4658341.6
A3: L-0002 | B3: TP03085 | C3: {=INDEX(Raw_Observations!$E$2:$E$1000,MATCH(1,(Raw_Observations!$A$2:$A$1000=A3)*(Raw_Observations!$B$2:$B$1000=B3),0))} -> 3520202 | D3: =MAX(IF(COUNTIFS(Raw_Observations!$A:$A,A3,Raw_Observations!$B:$B,B3)=0,"",SUMIFS(Raw_Observations!$F:$F,Raw_Observations!$A:$A,A3,Raw_Observations!$B:$B,B3)-TODAY()),0) -> 15 | E3: =IFERROR(LOOKUP(2,1/((Bank_Rates!$A$2:$A$100=LOOKUP(2,1/((Raw_Observations!$A$2:$A$1000=A3)*(Raw_Observations!$B$2:$B$1000=B3)),Raw_Observations!$H$2:$H$1000))*(Bank_Rates!$B$2:$B$100=LOOKUP(2,1/((Bank_Rates!$A$2:$A$100=LOOKUP(2,1/((Raw_Observations!$A$2:$A$1000=A3)*(Raw_Observations!$B$2:$B$1000=B3)),Raw_Observations!$H$2:$H$1000))*(Bank_Rates!$B$2:$B$100<=TODAY())),Bank_Rates!$B$2:$B$100))*(Bank_Rates!$D$2:$D$100<=D3)),Bank_Rates!$C$2:$C$100),"No Match") -> 0.04 | F3: {=INDEX(Raw_Observations!$K$2:$K$1000,MATCH(1,(Raw_Observations!$A$2:$A$1000=A3)*(Raw_Observations!$B$2:$B$1000=B3),0))} -> 0.026845322 | G3: 0.02 | H3: =E3+G3 -> 0.06 | I3: =C3/((1+E3+G3)^(D3/365)) -> 3511782.6
A4: L-0003 | B4: TP03093 | C4: {=INDEX(Raw_Observations!$E$2:$E$1000,MATCH(1,(Raw_Observations!$A$2:$A$1000=A4)*(Raw_Observations!$B$2:$B$1000=B4),0))} -> 4626551 | D4: =MAX(IF(COUNTIFS(Raw_Observations!$A:$A,A4,Raw_Observations!$B:$B,B4)=0,"",SUMIFS(Raw_Observations!$F:$F,Raw_Observations!$A:$A,A4,Raw_Observations!$B:$B,B4)-TODAY()),0) -> 15 | E4: =IFERROR(LOOKUP(2,1/((Bank_Rates!$A$2:$A$100=LOOKUP(2,1/((Raw_Observations!$A$2:$A$1000=A4)*(Raw_Observations!$B$2:$B$1000=B4)),Raw_Observations!$H$2:$H$1000))*(Bank_Rates!$B$2:$B$100=LOOKUP(2,1/((Bank_Rates!$A$2:$A$100=LOOKUP(2,1/((Raw_Observations!$A$2:$A$1000=A4)*(Raw_Observations!$B$2:$B$1000=B4)),Raw_Observations!$H$2:$H$1000))*(Bank_Rates!$B$2:$B$100<=TODAY())),Bank_Rates!$B$2:$B$100))*(Bank_Rates!$D$2:$D$100<=D4)),Bank_Rates!$C$2:$C$100),"No Match") -> 0.04 | F4: {=INDEX(Raw_Observations!$K$2:$K$1000,MATCH(1,(Raw_Observations!$A$2:$A$1000=A4)*(Raw_Observations!$B$2:$B$1000=B4),0))} -> 0.026879994 | G4: 0.02 | H4: =E4+G4 -> 0.06 | I4: =C4/((1+E4+G4)^(D4/365)) -> 4615485.5
A5: L-0004 | B5: TP03104 | C5: {=INDEX(Raw_Observations!$E$2:$E$1000,MATCH(1,(Raw_Observations!$A$2:$A$1000=A5)*(Raw_Observations!$B$2:$B$1000=B5),0))} -> 3520202 | D5: =MAX(IF(COUNTIFS(Raw_Observations!$A:$A,A5,Raw_Observations!$B:$B,B5)=0,"",SUMIFS(Raw_Observations!$F:$F,Raw_Observations!$A:$A,A5,Raw_Observations!$B:$B,B5)-TODAY()),0) -> 15 | E5: =IFERROR(LOOKUP(2,1/((Bank_Rates!$A$2:$A$100=LOOKUP(2,1/((Raw_Observations!$A$2:$A$1000=A5)*(Raw_Observations!$B$2:$B$1000=B5)),Raw_Observations!$H$2:$H$1000))*(Bank_Rates!$B$2:$B$100=LOOKUP(2,1/((Bank_Rates!$A$2:$A$100=LOOKUP(2,1/((Raw_Observations!$A$2:$A$1000=A5)*(Raw_Observations!$B$2:$B$1000=B5)),Raw_Observations!$H$2:$H$1000))*(Bank_Rates!$B$2:$B$100<=TODAY())),Bank_Rates!$B$2:$B$100))*(Bank_Rates!$D$2:$D$100<=D5)),Bank_Rates!$C$2:$C$100),"No Match") -> 0.04 | F5: {=INDEX(Raw_Observations!$K$2:$K$1000,MATCH(1,(Raw_Observations!$A$2:$A$1000=A5)*(Raw_Observations!$B$2:$B$1000=B5),0))} -> 0.02631387 | G5: 0.02 | H5: =E5+G5 -> 0.06 | I5: =C5/((1+E5+G5)^(D5/365)) -> 3511782.6
A6: =IF(B6<>"","L-"&TEXT(ROW()-1,"0000"),"") -> L-0005 | B6: TP00964 | C6: {=INDEX(Raw_Observations!$E$2:$E$1000,MATCH(1,(Raw_Observations!$A$2:$A$1000=A6)*(Raw_Observations!$B$2:$B$1000=B6),0))} -> 6749674 | D6: =MAX(IF(COUNTIFS(Raw_Observations!$A:$A,A6,Raw_Observations!$B:$B,B6)=0,"",SUMIFS(Raw_Observations!$F:$F,Raw_Observations!$A:$A,A6,Raw_Observations!$B:$B,B6)-TODAY()),0) -> 48 | E6: =IFERROR(LOOKUP(2,1/((Bank_Rates!$A$2:$A$100=LOOKUP(2,1/((Raw_Observations!$A$2:$A$1000=A6)*(Raw_Observations!$B$2:$B$1000=B6)),Raw_Observations!$H$2:$H$1000))*(Bank_Rates!$B$2:$B$100=LOOKUP(2,1/((Bank_Rates!$A$2:$A$100=LOOKUP(2,1/((Raw_Observations!$A$2:$A$1000=A6)*(Raw_Observations!$B$2:$B$1000=B6)),Raw_Observations!$H$2:$H$1000))*(Bank_Rates!$B$2:$B$100<=TODAY())),Bank_Rates!$B$2:$B$100))*(Bank_Rates!$D$2:$D$100<=D6)),Bank_Rates!$C$2:$C$100),"No Match") -> 0.065 | F6: {=INDEX(Raw_Observations!$K$2:$K$1000,MATCH(1,(Raw_Observations!$A$2:$A$1000=A6)*(Raw_Observations!$B$2:$B$1000=B6),0))} -> 0.0060869004 | G6: 0.002 | H6: =E6+G6 -> 0.067 | I6: =C6/((1+E6+G6)^(D6/365)) -> 6692355.2
A7: =IF(B7<>"","L-"&TEXT(ROW()-1,"0000"),"") -> L-0006 | B7: TP03429 | C7: {=INDEX(Raw_Observations!$E$2:$E$1000,MATCH(1,(Raw_Observations!$A$2:$A$1000=A7)*(Raw_Observations!$B$2:$B$1000=B7),0))} -> 20826744 | D7: =MAX(IF(COUNTIFS(Raw_Observations!$A:$A,A7,Raw_Observations!$B:$B,B7)=0,"",SUMIFS(Raw_Observations!$F:$F,Raw_Observations!$A:$A,A7,Raw_Observations!$B:$B,B7)-TODAY()),0) -> 173 | E7: =IFERROR(LOOKUP(2,1/((Bank_Rates!$A$2:$A$100=LOOKUP(2,1/((Raw_Observations!$A$2:$A$1000=A7)*(Raw_Observations!$B$2:$B$1000=B7)),Raw_Observations!$H$2:$H$1000))*(Bank_Rates!$B$2:$B$100=LOOKUP(2,1/((Bank_Rates!$A$2:$A$100=LOOKUP(2,1/((Raw_Observations!$A$2:$A$1000=A7)*(Raw_Observations!$B$2:$B$1000=B7)),Raw_Observations!$H$2:$H$1000))*(Bank_Rates!$B$2:$B$100<=TODAY())),Bank_Rates!$B$2:$B$100))*(Bank_Rates!$D$2:$D$100<=D7)),Bank_Rates!$C$2:$C$100),"No Match") -> 0.07 | F7: {=INDEX(Raw_Observations!$K$2:$K$1000,MATCH(1,(Raw_Observations!$A$2:$A$1000=A7)*(Raw_Observations!$B$2:$B$1000=B7),0))} -> 0.0066851073 | G7: 0.003 | H7: =E7+G7 -> 0.073 | I7: =C7/((1+E7+G7)^(D7/365)) -> 20142712
A8: =IF(B8<>"","L-"&TEXT(ROW()-1,"0000"),"") -> L-0007 | B8: TP00537 | C8: {=INDEX(Raw_Observations!$E$2:$E$1000,MATCH(1,(Raw_Observations!$A$2:$A$1000=A8)*(Raw_Observations!$B$2:$B$1000=B8),0))} -> 30297331 | D8: =MAX(IF(COUNTIFS(Raw_Observations!$A:$A,A8,Raw_Observations!$B:$B,B8)=0,"",SUMIFS(Raw_Observations!$F:$F,Raw_Observations!$A:$A,A8,Raw_Observations!$B:$B,B8)-TODAY()),0) -> 89 | E8: =IFERROR(LOOKUP(2,1/((Bank_Rates!$A$2:$A$100=LOOKUP(2,1/((Raw_Observations!$A$2:$A$1000=A8)*(Raw_Observations!$B$2:$B$1000=B8)),Raw_Observations!$H$2:$H$1000))*(Bank_Rates!$B$2:$B$100=LOOKUP(2,1/((Bank_Rates!$A$2:$A$100=LOOKUP(2,1/((Raw_Observations!$A$2:$A$1000=A8)*(Raw_Observations!$B$2:$B$1000=B8)),Raw_Observations!$H$2:$H$1000))*(Bank_Rates!$B$2:$B$100<=TODAY())),Bank_Rates!$B$2:$B$100))*(Bank_Rates!$D$2:$D$100<=D8)),Bank_Rates!$C$2:$C$100),"No Match") -> 0.067 | F8: {=INDEX(Raw_Observations!$K$2:$K$1000,MATCH(1,(Raw_Observations!$A$2:$A$1000=A8)*(Raw_Observations!$B$2:$B$1000=B8),0))} -> 0.0089830705 | G8: 0.0034 | H8: =E8+G8 -> 0.0704 | I8: =C8/((1+E8+G8)^(D8/365)) -> 29798883
A9: =IF(B9<>"","L-"&TEXT(ROW()-1,"0000"),"") -> L-0008 | B9: TP01034 | C9: {=INDEX(Raw_Observations!$E$2:$E$1000,MATCH(1,(Raw_Observations!$A$2:$A$1000=A9)*(Raw_Observations!$B$2:$B$1000=B9),0))} -> 31206091 | D9: =MAX(IF(COUNTIFS(Raw_Observations!$A:$A,A9,Raw_Observations!$B:$B,B9)=0,"",SUMIFS(Raw_Observations!$F:$F,Raw_Observations!$A:$A,A9,Raw_Observations!$B:$B,B9)-TODAY()),0) -> 174 | E9: =IFERROR(LOOKUP(2,1/((Bank_Rates!$A$2:$A$100=LOOKUP(2,1/((Raw_Observations!$A$2:$A$1000=A9)*(Raw_Observations!$B$2:$B$1000=B9)),Raw_Observations!$H$2:$H$1000))*(Bank_Rates!$B$2:$B$100=LOOKUP(2,1/((Bank_Rates!$A$2:$A$100=LOOKUP(2,1/((Raw_Observations!$A$2:$A$1000=A9)*(Raw_Observations!$B$2:$B$1000=B9)),Raw_Observations!$H$2:$H$1000))*(Bank_Rates!$B$2:$B$100<=TODAY())),Bank_Rates!$B$2:$B$100))*(Bank_Rates!$D$2:$D$100<=D9)),Bank_Rates!$C$2:$C$100),"No Match") -> 0.07 | F9: {=INDEX(Raw_Observations!$K$2:$K$1000,MATCH(1,(Raw_Observations!$A$2:$A$1000=A9)*(Raw_Observations!$B$2:$B$1000=B9),0))} -> 0.0074884785 | G9: 0.003 | H9: =E9+G9 -> 0.073 | I9: =C9/((1+E9+G9)^(D9/365)) -> 30175335
A10: =IF(B10<>"","L-"&TEXT(ROW()-1,"0000"),"") -> L-0009 | B10: TP00945 | C10: {=INDEX(Raw_Observations!$E$2:$E$1000,MATCH(1,(Raw_Observations!$A$2:$A$1000=A10)*(Raw_Observations!$B$2:$B$1000=B10),0))} -> 20110411 | D10: =MAX(IF(COUNTIFS(Raw_Observations!$A:$A,A10,Raw_Observations!$B:$B,B10)=0,"",SUMIFS(Raw_Observations!$F:$F,Raw_Observations!$A:$A,A10,Raw_Observations!$B:$B,B10)-TODAY()),0) -> 7 | E10: =IFERROR(LOOKUP(2,1/((Bank_Rates!$A$2:$A$100=LOOKUP(2,1/((Raw_Observations!$A$2:$A$1000=A10)*(Raw_Observations!$B$2:$B$1000=B10)),Raw_Observations!$H$2:$H$1000))*(Bank_Rates!$B$2:$B$100=LOOKUP(2,1/((Bank_Rates!$A$2:$A$100=LOOKUP(2,1/((Raw_Observations!$A$2:$A$1000=A10)*(Raw_Observations!$B$2:$B$1000=B10)),Raw_Observations!$H$2:$H$1000))*(Bank_Rates!$B$2:$B$100<=TODAY())),Bank_Rates!$B$2:$B$100))*(Bank_Rates!$D$2:$D$100<=D10)),Bank_Rates!$C$2:$C$100),"No Match") -> 0.04 | F10: {=INDEX(Raw_Observations!$K$2:$K$1000,MATCH(1,(Raw_Observations!$A$2:$A$1000=A10)*(Raw_Observations!$B$2:$B$1000=B10),0))} -> 0.027021452 | G10: 0.01 | H10: =E10+G10 -> 0.05 | I10: =C10/((1+E10+G10)^(D10/365)) -> 20091602
A11: L-0010 | B11: TP00558 | C11: {=INDEX(Raw_Observations!$E$2:$E$1000,MATCH(1,(Raw_Observations!$A$2:$A$1000=A11)*(Raw_Observations!$B$2:$B$1000=B11),0))} -> 50305612 | D11: =MAX(IF(COUNTIFS(Raw_Observations!$A:$A,A11,Raw_Observations!$B:$B,B11)=0,"",SUMIFS(Raw_Observations!$F:$F,Raw_Observations!$A:$A,A11,Raw_Observations!$B:$B,B11)-TODAY()),0) -> 9 | E11: =IFERROR(LOOKUP(2,1/((Bank_Rates!$A$2:$A$100=LOOKUP(2,1/((Raw_Observations!$A$2:$A$1000=A11)*(Raw_Observations!$B$2:$B$1000=B11)),Raw_Observations!$H$2:$H$1000))*(Bank_Rates!$B$2:$B$100=LOOKUP(2,1/((Bank_Rates!$A$2:$A$100=LOOKUP(2,1/((Raw_Observations!$A$2:$A$1000=A11)*(Raw_Observations!$B$2:$B$1000=B11)),Raw_Observations!$H$2:$H$1000))*(Bank_Rates!$B$2:$B$100<=TODAY())),Bank_Rates!$B$2:$B$100))*(Bank_Rates!$D$2:$D$100<=D11)),Bank_Rates!$C$2:$C$100),"No Match") -> 0.04 | F11: {=INDEX(Raw_Observations!$K$2:$K$1000,MATCH(1,(Raw_Observations!$A$2:$A$1000=A11)*(Raw_Observations!$B$2:$B$1000=B11),0))} -> 0.026039853 | G11: 0.017 | H11: =E11+G11 -> 0.057 | I11: =C11/((1+E11+G11)^(D11/365)) -> 50236897
A12: L-0011 | B12: TP00877 | C12: {=INDEX(Raw_Observations!$E$2:$E$1000,MATCH(1,(Raw_Observations!$A$2:$A$1000=A12)*(Raw_Observations!$B$2:$B$1000=B12),0))} -> 9963029 | D12: =MAX(IF(COUNTIFS(Raw_Observations!$A:$A,A12,Raw_Observations!$B:$B,B12)=0,"",SUMIFS(Raw_Observations!$F:$F,Raw_Observations!$A:$A,A12,Raw_Observations!$B:$B,B12)-TODAY()),0) -> 19 | E12: =IFERROR(LOOKUP(2,1/((Bank_Rates!$A$2:$A$100=LOOKUP(2,1/((Raw_Observations!$A$2:$A$1000=A12)*(Raw_Observations!$B$2:$B$1000=B12)),Raw_Observations!$H$2:$H$1000))*(Bank_Rates!$B$2:$B$100=LOOKUP(2,1/((Bank_Rates!$A$2:$A$100=LOOKUP(2,1/((Raw_Observations!$A$2:$A$1000=A12)*(Raw_Observations!$B$2:$B$1000=B12)),Raw_Observations!$H$2:$H$1000))*(Bank_Rates!$B$2:$B$100<=TODAY())),Bank_Rates!$B$2:$B$100))*(Bank_Rates!$D$2:$D$100<=D12)),Bank_Rates!$C$2:$C$100),"No Match") -> 0.04 | F12: {=INDEX(Raw_Observations!$K$2:$K$1000,MATCH(1,(Raw_Observations!$A$2:$A$1000=A12)*(Raw_Observations!$B$2:$B$1000=B12),0))} -> 0.02816072 | G12: 0.017 | H12: =E12+G12 -> 0.057 | I12: =C12/((1+E12+G12)^(D12/365)) -> 9934320.7
A13: L-0012 | B13: TP01801 | C13: {=INDEX(Raw_Observations!$E$2:$E$1000,MATCH(1,(Raw_Observations!$A$2:$A$1000=A13)*(Raw_Observations!$B$2:$B$1000=B13),0))} -> 6584707 | D13: =MAX(IF(COUNTIFS(Raw_Observations!$A:$A,A13,Raw_Observations!$B:$B,B13)=0,"",SUMIFS(Raw_Observations!$F:$F,Raw_Observations!$A:$A,A13,Raw_Observations!$B:$B,B13)-TODAY()),0) -> 12 | E13: =IFERROR(LOOKUP(2,1/((Bank_Rates!$A$2:$A$100=LOOKUP(2,1/((Raw_Observations!$A$2:$A$1000=A13)*(Raw_Observations!$B$2:$B$1000=B13)),Raw_Observations!$H$2:$H$1000))*(Bank_Rates!$B$2:$B$100=LOOKUP(2,1/((Bank_Rates!$A$2:$A$100=LOOKUP(2,1/((Raw_Observations!$A$2:$A$1000=A13)*(Raw_Observations!$B$2:$B$1000=B13)),Raw_Observations!$H$2:$H$1000))*(Bank_Rates!$B$2:$B$100<=TODAY())),Bank_Rates!$B$2:$B$100))*(Bank_Rates!$D$2:$D$100<=D13)),Bank_Rates!$C$2:$C$100),"No Match") -> 0.04 | F13: {=INDEX(Raw_Observations!$K$2:$K$1000,MATCH(1,(Raw_Observations!$A$2:$A$1000=A13)*(Raw_Observations!$B$2:$B$1000=B13),0))} -> 0.081407238 | G13: 0.017 | H13: =E13+G13 -> 0.057 | I13: =C13/((1+E13+G13)^(D13/365)) -> 6572717.2
A14: L-0013 | B14: TP00397 | C14: {=INDEX(Raw_Observations!$E$2:$E$1000,MATCH(1,(Raw_Observations!$A$2:$A$1000=A14)*(Raw_Observations!$B$2:$B$1000=B14),0))} -> 4574570 | D14: =MAX(IF(COUNTIFS(Raw_Observations!$A:$A,A14,Raw_Observations!$B:$B,B14)=0,"",SUMIFS(Raw_Observations!$F:$F,Raw_Observations!$A:$A,A14,Raw_Observations!$B:$B,B14)-TODAY()),0) -> 24 | E14: =IFERROR(LOOKUP(2,1/((Bank_Rates!$A$2:$A$100=LOOKUP(2,1/((Raw_Observations!$A$2:$A$1000=A14)*(Raw_Observations!$B$2:$B$1000=B14)),Raw_Observations!$H$2:$H$1000))*(Bank_Rates!$B$2:$B$100=LOOKUP(2,1/((Bank_Rates!$A$2:$A$100=LOOKUP(2,1/((Raw_Observations!$A$2:$A$1000=A14)*(Raw_Observations!$B$2:$B$1000=B14)),Raw_Observations!$H$2:$H$1000))*(Bank_Rates!$B$2:$B$100<=TODAY())),Bank_Rates!$B$2:$B$100))*(Bank_Rates!$D$2:$D$100<=D14)),Bank_Rates!$C$2:$C$100),"No Match") -> 0.04 | F14: {=INDEX(Raw_Observations!$K$2:$K$1000,MATCH(1,(Raw_Observations!$A$2:$A$1000=A14)*(Raw_Observations!$B$2:$B$1000=B14),0))} -> 0.026926527 | G14: 0.017 | H14: =E14+G14 -> 0.057 | I14: =C14/((1+E14+G14)^(D14/365)) -> 4557925.9
A15: L-0014 | B15: TP93098 | C15: {=INDEX(Raw_Observations!$E$2:$E$1000,MATCH(1,(Raw_Observations!$A$2:$A$1000=A15)*(Raw_Observations!$B$2:$B$1000=B15),0))} -> 51993393 | D15: =MAX(IF(COUNTIFS(Raw_Observations!$A:$A,A15,Raw_Observations!$B:$B,B15)=0,"",SUMIFS(Raw_Observations!$F:$F,Raw_Observations!$A:$A,A15,Raw_Observations!$B:$B,B15)-TODAY()),0) -> 182 | E15: =IFERROR(LOOKUP(2,1/((Bank_Rates!$A$2:$A$100=LOOKUP(2,1/((Raw_Observations!$A$2:$A$1000=A15)*(Raw_Observations!$B$2:$B$1000=B15)),Raw_Observations!$H$2:$H$1000))*(Bank_Rates!$B$2:$B$100=LOOKUP(2,1/((Bank_Rates!$A$2:$A$100=LOOKUP(2,1/((Raw_Observations!$A$2:$A$1000=A15)*(Raw_Observations!$B$2:$B$1000=B15)),Raw_Observations!$H$2:$H$1000))*(Bank_Rates!$B$2:$B$100<=TODAY())),Bank_Rates!$B$2:$B$100))*(Bank_Rates!$D$2:$D$100<=D15)),Bank_Rates!$C$2:$C$100),"No Match") -> 0.071 | F15: {=INDEX(Raw_Observations!$K$2:$K$1000,MATCH(1,(Raw_Observations!$A$2:$A$1000=A15)*(Raw_Observations!$B$2:$B$1000=B15),0))} -> 0.011432327 | G15: 0.0093 | H15: =E15+G15 -> 0.0803 | I15: =C15/((1+E15+G15)^(D15/365)) -> 50029012

Sheet Buy_History
A1: Listing ID | B1: CD ID | C1: Buy Timestamp
A2: =IF(B2<>"","L-"&TEXT(ROW()-1,"0000"),"") -> L-0001 | B2: TP03077 | C2: 46253
A3: =IF(B3<>"","L-"&TEXT(ROW()-1,"0000"),"") -> L-0002 | B3: TP03085 | C3: 46253
A4: =IF(B4<>"","L-"&TEXT(ROW()-1,"0000"),"") -> L-0003 | B4: TP03093 | C4: 46253
A5: =IF(B5<>"","L-"&TEXT(ROW()-1,"0000"),"") -> L-0004 | B5: TP03104 | C5: 46253
A6: L-0005 | B6: TP00964 | C6: 46245
A7: L-0006 | B7: TP03429 | C7: 46247
A8: L-0007 | B8: TP00537 | C8: 46248
A9: L-0008 | B9: TP01034 | C9: 46248
A10: L-0009 | B10: TP00945 | C10: 46251
A11: L-0010 | B11: TP00558 | C11: 46256
A12: =IF(B12<>"","L-"&TEXT(ROW()-1,"0000"),"")
A13: =IF(B13<>"","L-"&TEXT(ROW()-1,"0000"),"")
A14: =IF(B14<>"","L-"&TEXT(ROW()-1,"0000"),"")
A15: =IF(B15<>"","L-"&TEXT(ROW()-1,"0000"),"")
A16: =IF(B16<>"","L-"&TEXT(ROW()-1,"0000"),"")
A17: =IF(B17<>"","L-"&TEXT(ROW()-1,"0000"),"")
A18: =IF(B18<>"","L-"&TEXT(ROW()-1,"0000"),"")
A19: =IF(B19<>"","L-"&TEXT(ROW()-1,"0000"),"")
A20: =IF(B20<>"","L-"&TEXT(ROW()-1,"0000"),"")
A21: =IF(B21<>"","L-"&TEXT(ROW()-1,"0000"),"")
A22: =IF(B22<>"","L-"&TEXT(ROW()-1,"0000"),"")
A23: =IF(B23<>"","L-"&TEXT(ROW()-1,"0000"),"")
... A501: =IF(B501<>"","L-"&TEXT(ROW()-1,"0000"),"")

Sheet Order_History
A1: Listing ID | B1: CD ID | C1: Order Timestamp | D1: Asking Price ($)
A2: L-0001 | B2: TP03077 | C2: 46254 | D2: 4656111.1
A3: L-0002 | B3: TP03085 | C3: 46254 | D3: 3510101.1
A4: L-0003 | B4: TP03093 | C4: 46254 | D4: 4613275.5
A5: L-0004 | B5: TP03104 | C5: 46254 | D5: 3510101.1
A6: L-0005 | B6: TP00964 | C6: 46249 | D6: 6673000
A7: L-0006 | B7: TP03429 | C7: 46248 | D7: 20074367
A8: L-0007 | B8: TP00537 | C8: 46248 | D8: 29702912
A9: L-0008 | B9: TP01034 | C9: 46249 | D9: 30067117
A10: L-0009 | B10: TP00945 | C10: 46253 | D10: 20087893
A11: L-0010 | B11: TP00558 | C11: 46256 | D11: 50229268

Sheet Sell_History
A1: Listing ID | B1: CD ID | C1: Matched Timestamp
A2: L-0001 | B2: TP03077 | C2: 46255
A3: L-0002 | B3: TP03085 | C3: 46255
A4: L-0003 | B4: TP03093 | C4: 46255
A5: L-0004 | B5: TP03104 | C5: 46255
A6: L-0005 | B6: TP00964 | C6: 46249
A7: L-0006 | B7: TP03429 | C7: 46248
A8: L-0007 | B8: TP00537 | C8: 46248
A9: L-0008 | B9: TP01034 | C9: 46249
A10: L-0009 | B10: TP00945 | C10: 46253
A11: L-0010 | B11: TP00558 | C11: 46257

Sheet Trade_Results
A1: Listing ID | B1: CD ID | C1: Buy Timestamp | D1: Sell Timestamp | E1: Buy Price ($) | F1: Sell Price ($) | G1: Liquidity Spread | H1: Gross Profit ($) | I1: Tax ($) | J1: Fee ($) | K1: Net Profit ($) | L1: ROI | M1: Holding Period (Days) | N1: Effective Annual Return
A2: L-0001 | B2: TP03077 | C2: =IF(COUNTIFS(Buy_History!$A:$A,A2,Buy_History!$B:$B,B2)=0,"",SUMIFS(Buy_History!$C:$C,Buy_History!$A:$A,A2,Buy_History!$B:$B,B2)) -> 46253 | D2: =IF(COUNTIFS(Sell_History!$A:$A,A2,Sell_History!$B:$B,B2)=0,"",SUMIFS(Sell_History!$C:$C,Sell_History!$A:$A,A2,Sell_History!$B:$B,B2)) -> 46255 | E2: =IF(COUNTIFS(Raw_Observations!$A:$A,A2,Raw_Observations!$B:$B,B2)=0,"",SUMIFS(Raw_Observations!$D:$D,Raw_Observations!$A:$A,A2,Raw_Observations!$B:$B,B2)) -> 4653638 | F2: =IF(COUNTIFS(Order_History!$A:$A,A2,Order_History!$B:$B,B2)=0,"",SUMIFS(Order_History!$D:$D,Order_History!$A:$A,A2,Order_History!$B:$B,B2)) -> 4656111.1 | G2: =IF(COUNTIFS(Pricing!$A:$A,A2,Pricing!$B:$B,B2)=0,"",SUMIFS(Pricing!$G:$G,Pricing!$A:$A,A2,Pricing!$B:$B,B2)) -> 0.02 | H2: =IF(OR(E2="",F2=""),"",F2-E2) -> 2473.1321 | I2: 0 | J2: 0 | K2: =IF(H2="","",H2-I2-J2) -> 2473.1321 | L2: =IF(OR(K2="",E2=""),"",K2/E2) -> 0.00053144059 | M2: =IF(OR(C2="",D2=""),"",MAX(1,ROUNDUP(D2-C2,0))) -> 2 | N2: =IF(OR(L2="",M2=""),"",(1+L2)^(365/M2)-1) -> 0.10181866
A3: L-0002 | B3: TP03085 | C3: =IF(COUNTIFS(Buy_History!$A:$A,A3,Buy_History!$B:$B,B3)=0,"",SUMIFS(Buy_History!$C:$C,Buy_History!$A:$A,A3,Buy_History!$B:$B,B3)) -> 46253 | D3: =IF(COUNTIFS(Sell_History!$A:$A,A3,Sell_History!$B:$B,B3)=0,"",SUMIFS(Sell_History!$C:$C,Sell_History!$A:$A,A3,Sell_History!$B:$B,B3)) -> 46255 | E3: =IF(COUNTIFS(Raw_Observations!$A:$A,A3,Raw_Observations!$B:$B,B3)=0,"",SUMIFS(Raw_Observations!$D:$D,Raw_Observations!$A:$A,A3,Raw_Observations!$B:$B,B3)) -> 3508365 | F3: =IF(COUNTIFS(Order_History!$A:$A,A3,Order_History!$B:$B,B3)=0,"",SUMIFS(Order_History!$D:$D,Order_History!$A:$A,A3,Order_History!$B:$B,B3)) -> 3510101.1 | G3: =IF(COUNTIFS(Pricing!$A:$A,A3,Pricing!$B:$B,B3)=0,"",SUMIFS(Pricing!$G:$G,Pricing!$A:$A,A3,Pricing!$B:$B,B3)) -> 0.02 | H3: =IF(OR(E3="",F3=""),"",F3-E3) -> 1736.0953 | I3: 0 | J3: 0 | K3: =IF(H3="","",H3-I3-J3) -> 1736.0953 | L3: =IF(OR(K3="",E3=""),"",K3/E3) -> 0.00049484454 | M3: =IF(OR(C3="",D3=""),"",MAX(1,ROUNDUP(D3-C3,0))) -> 2 | N3: =IF(OR(L3="",M3=""),"",(1+L3)^(365/M3)-1) -> 0.094488128
A4: L-0003 | B4: TP03093 | C4: =IF(COUNTIFS(Buy_History!$A:$A,A4,Buy_History!$B:$B,B4)=0,"",SUMIFS(Buy_History!$C:$C,Buy_History!$A:$A,A4,Buy_History!$B:$B,B4)) -> 46253 | D4: =IF(COUNTIFS(Sell_History!$A:$A,A4,Sell_History!$B:$B,B4)=0,"",SUMIFS(Sell_History!$C:$C,Sell_History!$A:$A,A4,Sell_History!$B:$B,B4)) -> 46255 | E4: =IF(COUNTIFS(Raw_Observations!$A:$A,A4,Raw_Observations!$B:$B,B4)=0,"",SUMIFS(Raw_Observations!$D:$D,Raw_Observations!$A:$A,A4,Raw_Observations!$B:$B,B4)) -> 4610986 | F4: =IF(COUNTIFS(Order_History!$A:$A,A4,Order_History!$B:$B,B4)=0,"",SUMIFS(Order_History!$D:$D,Order_History!$A:$A,A4,Order_History!$B:$B,B4)) -> 4613275.5 | G4: =IF(COUNTIFS(Pricing!$A:$A,A4,Pricing!$B:$B,B4)=0,"",SUMIFS(Pricing!$G:$G,Pricing!$A:$A,A4,Pricing!$B:$B,B4)) -> 0.02 | H4: =IF(OR(E4="",F4=""),"",F4-E4) -> 2289.5258 | I4: 0 | J4: 0 | K4: =IF(H4="","",H4-I4-J4) -> 2289.5258 | L4: =IF(OR(K4="",E4=""),"",K4/E4) -> 0.00049653713 | M4: =IF(OR(C4="",D4=""),"",MAX(1,ROUNDUP(D4-C4,0))) -> 2 | N4: =IF(OR(L4="",M4=""),"",(1+L4)^(365/M4)-1) -> 0.094826099
A5: L-0004 | B5: TP03104 | C5: =IF(COUNTIFS(Buy_History!$A:$A,A5,Buy_History!$B:$B,B5)=0,"",SUMIFS(Buy_History!$C:$C,Buy_History!$A:$A,A5,Buy_History!$B:$B,B5)) -> 46253 | D5: =IF(COUNTIFS(Sell_History!$A:$A,A5,Sell_History!$B:$B,B5)=0,"",SUMIFS(Sell_History!$C:$C,Sell_History!$A:$A,A5,Sell_History!$B:$B,B5)) -> 46255 | E5: =IF(COUNTIFS(Raw_Observations!$A:$A,A5,Raw_Observations!$B:$B,B5)=0,"",SUMIFS(Raw_Observations!$D:$D,Raw_Observations!$A:$A,A5,Raw_Observations!$B:$B,B5)) -> 3508456 | F5: =IF(COUNTIFS(Order_History!$A:$A,A5,Order_History!$B:$B,B5)=0,"",SUMIFS(Order_History!$D:$D,Order_History!$A:$A,A5,Order_History!$B:$B,B5)) -> 3510101.1 | G5: =IF(COUNTIFS(Pricing!$A:$A,A5,Pricing!$B:$B,B5)=0,"",SUMIFS(Pricing!$G:$G,Pricing!$A:$A,A5,Pricing!$B:$B,B5)) -> 0.02 | H5: =IF(OR(E5="",F5=""),"",F5-E5) -> 1645.0953 | I5: 0 | J5: 0 | K5: =IF(H5="","",H5-I5-J5) -> 1645.0953 | L5: =IF(OR(K5="",E5=""),"",K5/E5) -> 0.00046889437 | M5: =IF(OR(C5="",D5=""),"",MAX(1,ROUNDUP(D5-C5,0))) -> 2 | N5: =IF(OR(L5="",M5=""),"",(1+L5)^(365/M5)-1) -> 0.089319475
A6: L-0005 | B6: TP00964 | C6: =IF(COUNTIFS(Buy_History!$A:$A,A6,Buy_History!$B:$B,B6)=0,"",SUMIFS(Buy_History!$C:$C,Buy_History!$A:$A,A6,Buy_History!$B:$B,B6)) -> 46245 | D6: =IF(COUNTIFS(Sell_History!$A:$A,A6,Sell_History!$B:$B,B6)=0,"",SUMIFS(Sell_History!$C:$C,Sell_History!$A:$A,A6,Sell_History!$B:$B,B6)) -> 46249 | E6: =IF(COUNTIFS(Raw_Observations!$A:$A,A6,Raw_Observations!$B:$B,B6)=0,"",SUMIFS(Raw_Observations!$D:$D,Raw_Observations!$A:$A,A6,Raw_Observations!$B:$B,B6)) -> 6671860 | F6: =IF(COUNTIFS(Order_History!$A:$A,A6,Order_History!$B:$B,B6)=0,"",SUMIFS(Order_History!$D:$D,Order_History!$A:$A,A6,Order_History!$B:$B,B6)) -> 6673000 | G6: =IF(COUNTIFS(Pricing!$A:$A,A6,Pricing!$B:$B,B6)=0,"",SUMIFS(Pricing!$G:$G,Pricing!$A:$A,A6,Pricing!$B:$B,B6)) -> 0.002 | H6: =IF(OR(E6="",F6=""),"",F6-E6) -> 1140 | I6: 0 | J6: 0 | K6: =IF(H6="","",H6-I6-J6) -> 1140 | L6: =IF(OR(K6="",E6=""),"",K6/E6) -> 0.00017086689 | M6: =IF(OR(C6="",D6=""),"",MAX(1,ROUNDUP(D6-C6,0))) -> 4 | N6: =IF(OR(L6="",M6=""),"",(1+L6)^(365/M6)-1) -> 0.015712435
A7: L-0006 | B7: TP03429 | C7: =IF(COUNTIFS(Buy_History!$A:$A,A7,Buy_History!$B:$B,B7)=0,"",SUMIFS(Buy_History!$C:$C,Buy_History!$A:$A,A7,Buy_History!$B:$B,B7)) -> 46247 | D7: =IF(COUNTIFS(Sell_History!$A:$A,A7,Sell_History!$B:$B,B7)=0,"",SUMIFS(Sell_History!$C:$C,Sell_History!$A:$A,A7,Sell_History!$B:$B,B7)) -> 46248 | E7: =IF(COUNTIFS(Raw_Observations!$A:$A,A7,Raw_Observations!$B:$B,B7)=0,"",SUMIFS(Raw_Observations!$D:$D,Raw_Observations!$A:$A,A7,Raw_Observations!$B:$B,B7)) -> 20060000 | F7: =IF(COUNTIFS(Order_History!$A:$A,A7,Order_History!$B:$B,B7)=0,"",SUMIFS(Order_History!$D:$D,Order_History!$A:$A,A7,Order_History!$B:$B,B7)) -> 20074367 | G7: =IF(COUNTIFS(Pricing!$A:$A,A7,Pricing!$B:$B,B7)=0,"",SUMIFS(Pricing!$G:$G,Pricing!$A:$A,A7,Pricing!$B:$B,B7)) -> 0.003 | H7: =IF(OR(E7="",F7=""),"",F7-E7) -> 14367 | I7: 0 | J7: 0 | K7: =IF(H7="","",H7-I7-J7) -> 14367 | L7: =IF(OR(K7="",E7=""),"",K7/E7) -> 0.0007162014 | M7: =IF(OR(C7="",D7=""),"",MAX(1,ROUNDUP(D7-C7,0))) -> 1 | N7: =IF(OR(L7="",M7=""),"",(1+L7)^(365/M7)-1) -> 0.29864309
A8: L-0007 | B8: TP00537 | C8: =IF(COUNTIFS(Buy_History!$A:$A,A8,Buy_History!$B:$B,B8)=0,"",SUMIFS(Buy_History!$C:$C,Buy_History!$A:$A,A8,Buy_History!$B:$B,B8)) -> 46248 | D8: =IF(COUNTIFS(Sell_History!$A:$A,A8,Sell_History!$B:$B,B8)=0,"",SUMIFS(Sell_History!$C:$C,Sell_History!$A:$A,A8,Sell_History!$B:$B,B8)) -> 46248 | E8: =IF(COUNTIFS(Raw_Observations!$A:$A,A8,Raw_Observations!$B:$B,B8)=0,"",SUMIFS(Raw_Observations!$D:$D,Raw_Observations!$A:$A,A8,Raw_Observations!$B:$B,B8)) -> 29685213 | F8: =IF(COUNTIFS(Order_History!$A:$A,A8,Order_History!$B:$B,B8)=0,"",SUMIFS(Order_History!$D:$D,Order_History!$A:$A,A8,Order_History!$B:$B,B8)) -> 29702912 | G8: =IF(COUNTIFS(Pricing!$A:$A,A8,Pricing!$B:$B,B8)=0,"",SUMIFS(Pricing!$G:$G,Pricing!$A:$A,A8,Pricing!$B:$B,B8)) -> 0.0034 | H8: =IF(OR(E8="",F8=""),"",F8-E8) -> 17699 | I8: 0 | J8: 0 | K8: =IF(H8="","",H8-I8-J8) -> 17699 | L8: =IF(OR(K8="",E8=""),"",K8/E8) -> 0.00059622277 | M8: =IF(OR(C8="",D8=""),"",MAX(1,ROUNDUP(D8-C8,0))) -> 1 | N8: =IF(OR(L8="",M8=""),"",(1+L8)^(365/M8)-1) -> 0.24303561
A9: L-0008 | B9: TP01034 | C9: =IF(COUNTIFS(Buy_History!$A:$A,A9,Buy_History!$B:$B,B9)=0,"",SUMIFS(Buy_History!$C:$C,Buy_History!$A:$A,A9,Buy_History!$B:$B,B9)) -> 46248 | D9: =IF(COUNTIFS(Sell_History!$A:$A,A9,Sell_History!$B:$B,B9)=0,"",SUMIFS(Sell_History!$C:$C,Sell_History!$A:$A,A9,Sell_History!$B:$B,B9)) -> 46249 | E9: =IF(COUNTIFS(Raw_Observations!$A:$A,A9,Raw_Observations!$B:$B,B9)=0,"",SUMIFS(Raw_Observations!$D:$D,Raw_Observations!$A:$A,A9,Raw_Observations!$B:$B,B9)) -> 30046000 | F9: =IF(COUNTIFS(Order_History!$A:$A,A9,Order_History!$B:$B,B9)=0,"",SUMIFS(Order_History!$D:$D,Order_History!$A:$A,A9,Order_History!$B:$B,B9)) -> 30067117 | G9: =IF(COUNTIFS(Pricing!$A:$A,A9,Pricing!$B:$B,B9)=0,"",SUMIFS(Pricing!$G:$G,Pricing!$A:$A,A9,Pricing!$B:$B,B9)) -> 0.003 | H9: =IF(OR(E9="",F9=""),"",F9-E9) -> 21117 | I9: 0 | J9: 0 | K9: =IF(H9="","",H9-I9-J9) -> 21117 | L9: =IF(OR(K9="",E9=""),"",K9/E9) -> 0.00070282234 | M9: =IF(OR(C9="",D9=""),"",MAX(1,ROUNDUP(D9-C9,0))) -> 1 | N9: =IF(OR(L9="",M9=""),"",(1+L9)^(365/M9)-1) -> 0.29232129
A10: L-0009 | B10: TP00945 | C10: =IF(COUNTIFS(Buy_History!$A:$A,A10,Buy_History!$B:$B,B10)=0,"",SUMIFS(Buy_History!$C:$C,Buy_History!$A:$A,A10,Buy_History!$B:$B,B10)) -> 46251 | D10: =IF(COUNTIFS(Sell_History!$A:$A,A10,Sell_History!$B:$B,B10)=0,"",SUMIFS(Sell_History!$C:$C,Sell_History!$A:$A,A10,Sell_History!$B:$B,B10)) -> 46253 | E10: =IF(COUNTIFS(Raw_Observations!$A:$A,A10,Raw_Observations!$B:$B,B10)=0,"",SUMIFS(Raw_Observations!$D:$D,Raw_Observations!$A:$A,A10,Raw_Observations!$B:$B,B10)) -> 20064000 | F10: =IF(COUNTIFS(Order_History!$A:$A,A10,Order_History!$B:$B,B10)=0,"",SUMIFS(Order_History!$D:$D,Order_History!$A:$A,A10,Order_History!$B:$B,B10)) -> 20087893 | G10: =IF(COUNTIFS(Pricing!$A:$A,A10,Pricing!$B:$B,B10)=0,"",SUMIFS(Pricing!$G:$G,Pricing!$A:$A,A10,Pricing!$B:$B,B10)) -> 0.01 | H10: =IF(OR(E10="",F10=""),"",F10-E10) -> 23893 | I10: 0 | J10: 0 | K10: =IF(H10="","",H10-I10-J10) -> 23893 | L10: =IF(OR(K10="",E10=""),"",K10/E10) -> 0.0011908393 | M10: =IF(OR(C10="",D10=""),"",MAX(1,ROUNDUP(D10-C10,0))) -> 2 | N10: =IF(OR(L10="",M10=""),"",(1+L10)^(365/M10)-1) -> 0.2425912
A11: L-0010 | B11: TP00558 | C11: =IF(COUNTIFS(Buy_History!$A:$A,A11,Buy_History!$B:$B,B11)=0,"",SUMIFS(Buy_History!$C:$C,Buy_History!$A:$A,A11,Buy_History!$B:$B,B11)) -> 46256 | D11: =IF(COUNTIFS(Sell_History!$A:$A,A11,Sell_History!$B:$B,B11)=0,"",SUMIFS(Sell_History!$C:$C,Sell_History!$A:$A,A11,Sell_History!$B:$B,B11)) -> 46257 | E11: =IF(COUNTIFS(Raw_Observations!$A:$A,A11,Raw_Observations!$B:$B,B11)=0,"",SUMIFS(Raw_Observations!$D:$D,Raw_Observations!$A:$A,A11,Raw_Observations!$B:$B,B11)) -> 50217550 | F11: =IF(COUNTIFS(Order_History!$A:$A,A11,Order_History!$B:$B,B11)=0,"",SUMIFS(Order_History!$D:$D,Order_History!$A:$A,A11,Order_History!$B:$B,B11)) -> 50229268 | G11: =IF(COUNTIFS(Pricing!$A:$A,A11,Pricing!$B:$B,B11)=0,"",SUMIFS(Pricing!$G:$G,Pricing!$A:$A,A11,Pricing!$B:$B,B11)) -> 0.017 | H11: =IF(OR(E11="",F11=""),"",F11-E11) -> 11717.883 | I11: 0 | J11: 0 | K11: =IF(H11="","",H11-I11-J11) -> 11717.883 | L11: =IF(OR(K11="",E11=""),"",K11/E11) -> 0.00023334239 | M11: =IF(OR(C11="",D11=""),"",MAX(1,ROUNDUP(D11-C11,0))) -> 1 | N11: =IF(OR(L11="",M11=""),"",(1+L11)^(365/M11)-1) -> 0.088891316
C12: =IF(OR(A12="",B12=""),"",IFERROR(XLOOKUP(1,(Buy_History!$A$2:$A$501=A12)*(Buy_History!$B$2:$B$501=B12),Buy_History!$C$2:$C$501,""),"")) | D12: =IF(OR(A12="",B12=""),"",IFERROR(XLOOKUP(1,(Sell_History!$A$2:$A$501=A12)*(Sell_History!$B$2:$B$501=B12),Sell_History!$C$2:$C$501,""),"")) | E12: =IF(OR(A12="",B12=""),"",IFERROR(XLOOKUP(1,(Raw_Observations!$A$2:$A$1001=A12)*(Raw_Observations!$B$2:$B$1001=B12),Raw_Observations!$D$2:$D$1001,""),"")) | F12: =IF(OR(A12="",B12=""),"",IFERROR(XLOOKUP(1,(Order_History!$A$2:$A$501=A12)*(Order_History!$B$2:$B$501=B12),Order_History!$D$2:$D$501,""),"")) | G12: =IF(COUNTIFS(Pricing!$A:$A,A12,Pricing!$B:$B,B12)=0,"",SUMIFS(Pricing!$G:$G,Pricing!$A:$A,A12,Pricing!$B:$B,B12)) | H12: =IF(OR(E12="",F12=""),"",F12-E12) | I12: 0 | J12: 0 | K12: =IF(H12="","",H12-I12-J12) | L12: =IF(OR(K12="",E12=""),"",K12/E12) | M12: =IF(OR(C12="",D12=""),"",MAX(1,ROUNDUP(D12-C12,0))) | N12: =IF(OR(L12="",M12=""),"",(1+L12)^(365/M12)-1)
C13: =IF(OR(A13="",B13=""),"",IFERROR(XLOOKUP(1,(Buy_History!$A$2:$A$501=A13)*(Buy_History!$B$2:$B$501=B13),Buy_History!$C$2:$C$501,""),"")) | D13: =IF(OR(A13="",B13=""),"",IFERROR(XLOOKUP(1,(Sell_History!$A$2:$A$501=A13)*(Sell_History!$B$2:$B$501=B13),Sell_History!$C$2:$C$501,""),"")) | E13: =IF(OR(A13="",B13=""),"",IFERROR(XLOOKUP(1,(Raw_Observations!$A$2:$A$1001=A13)*(Raw_Observations!$B$2:$B$1001=B13),Raw_Observations!$D$2:$D$1001,""),"")) | F13: =IF(OR(A13="",B13=""),"",IFERROR(XLOOKUP(1,(Order_History!$A$2:$A$501=A13)*(Order_History!$B$2:$B$501=B13),Order_History!$D$2:$D$501,""),"")) | G13: =IF(COUNTIFS(Pricing!$A:$A,A13,Pricing!$B:$B,B13)=0,"",SUMIFS(Pricing!$G:$G,Pricing!$A:$A,A13,Pricing!$B:$B,B13)) | H13: =IF(OR(E13="",F13=""),"",F13-E13) | I13: 0 | J13: 0 | K13: =IF(H13="","",H13-I13-J13) | L13: =IF(OR(K13="",E13=""),"",K13/E13) | M13: =IF(OR(C13="",D13=""),"",MAX(1,ROUNDUP(D13-C13,0))) | N13: =IF(OR(L13="",M13=""),"",(1+L13)^(365/M13)-1)
C14: =IF(OR(A14="",B14=""),"",IFERROR(XLOOKUP(1,(Buy_History!$A$2:$A$501=A14)*(Buy_History!$B$2:$B$501=B14),Buy_History!$C$2:$C$501,""),"")) | D14: =IF(OR(A14="",B14=""),"",IFERROR(XLOOKUP(1,(Sell_History!$A$2:$A$501=A14)*(Sell_History!$B$2:$B$501=B14),Sell_History!$C$2:$C$501,""),"")) | E14: =IF(OR(A14="",B14=""),"",IFERROR(XLOOKUP(1,(Raw_Observations!$A$2:$A$1001=A14)*(Raw_Observations!$B$2:$B$1001=B14),Raw_Observations!$D$2:$D$1001,""),"")) | F14: =IF(OR(A14="",B14=""),"",IFERROR(XLOOKUP(1,(Order_History!$A$2:$A$501=A14)*(Order_History!$B$2:$B$501=B14),Order_History!$D$2:$D$501,""),"")) | G14: =IF(COUNTIFS(Pricing!$A:$A,A14,Pricing!$B:$B,B14)=0,"",SUMIFS(Pricing!$G:$G,Pricing!$A:$A,A14,Pricing!$B:$B,B14)) | H14: =IF(OR(E14="",F14=""),"",F14-E14) | I14: 0 | J14: 0 | K14: =IF(H14="","",H14-I14-J14) | L14: =IF(OR(K14="",E14=""),"",K14/E14) | M14: =IF(OR(C14="",D14=""),"",MAX(1,ROUNDUP(D14-C14,0))) | N14: =IF(OR(L14="",M14=""),"",(1+L14)^(365/M14)-1)
C15: =IF(OR(A15="",B15=""),"",IFERROR(XLOOKUP(1,(Buy_History!$A$2:$A$501=A15)*(Buy_History!$B$2:$B$501=B15),Buy_History!$C$2:$C$501,""),"")) | D15: =IF(OR(A15="",B15=""),"",IFERROR(XLOOKUP(1,(Sell_History!$A$2:$A$501=A15)*(Sell_History!$B$2:$B$501=B15),Sell_History!$C$2:$C$501,""),"")) | E15: =IF(OR(A15="",B15=""),"",IFERROR(XLOOKUP(1,(Raw_Observations!$A$2:$A$1001=A15)*(Raw_Observations!$B$2:$B$1001=B15),Raw_Observations!$D$2:$D$1001,""),"")) | F15: =IF(OR(A15="",B15=""),"",IFERROR(XLOOKUP(1,(Order_History!$A$2:$A$501=A15)*(Order_History!$B$2:$B$501=B15),Order_History!$D$2:$D$501,""),"")) | G15: =IF(COUNTIFS(Pricing!$A:$A,A15,Pricing!$B:$B,B15)=0,"",SUMIFS(Pricing!$G:$G,Pricing!$A:$A,A15,Pricing!$B:$B,B15)) | H15: =IF(OR(E15="",F15=""),"",F15-E15) | I15: 0 | J15: 0 | K15: =IF(H15="","",H15-I15-J15) | L15: =IF(OR(K15="",E15=""),"",K15/E15) | M15: =IF(OR(C15="",D15=""),"",MAX(1,ROUNDUP(D15-C15,0))) | N15: =IF(OR(L15="",M15=""),"",(1+L15)^(365/M15)-1)
C16: =IF(OR(A16="",B16=""),"",IFERROR(XLOOKUP(1,(Buy_History!$A$2:$A$501=A16)*(Buy_History!$B$2:$B$501=B16),Buy_History!$C$2:$C$501,""),"")) | D16: =IF(OR(A16="",B16=""),"",IFERROR(XLOOKUP(1,(Sell_History!$A$2:$A$501=A16)*(Sell_History!$B$2:$B$501=B16),Sell_History!$C$2:$C$501,""),"")) | E16: =IF(OR(A16="",B16=""),"",IFERROR(XLOOKUP(1,(Raw_Observations!$A$2:$A$1001=A16)*(Raw_Observations!$B$2:$B$1001=B16),Raw_Observations!$D$2:$D$1001,""),"")) | F16: =IF(OR(A16="",B16=""),"",IFERROR(XLOOKUP(1,(Order_History!$A$2:$A$501=A16)*(Order_History!$B$2:$B$501=B16),Order_History!$D$2:$D$501,""),"")) | G16: =IF(COUNTIFS(Pricing!$A:$A,A16,Pricing!$B:$B,B16)=0,"",SUMIFS(Pricing!$G:$G,Pricing!$A:$A,A16,Pricing!$B:$B,B16)) | H16: =IF(OR(E16="",F16=""),"",F16-E16) | I16: 0 | J16: 0 | K16: =IF(H16="","",H16-I16-J16) | L16: =IF(OR(K16="",E16=""),"",K16/E16) | M16: =IF(OR(C16="",D16=""),"",MAX(1,ROUNDUP(D16-C16,0))) | N16: =IF(OR(L16="",M16=""),"",(1+L16)^(365/M16)-1)
C17: =IF(OR(A17="",B17=""),"",IFERROR(XLOOKUP(1,(Buy_History!$A$2:$A$501=A17)*(Buy_History!$B$2:$B$501=B17),Buy_History!$C$2:$C$501,""),"")) | D17: =IF(OR(A17="",B17=""),"",IFERROR(XLOOKUP(1,(Sell_History!$A$2:$A$501=A17)*(Sell_History!$B$2:$B$501=B17),Sell_History!$C$2:$C$501,""),"")) | E17: =IF(OR(A17="",B17=""),"",IFERROR(XLOOKUP(1,(Raw_Observations!$A$2:$A$1001=A17)*(Raw_Observations!$B$2:$B$1001=B17),Raw_Observations!$D$2:$D$1001,""),"")) | F17: =IF(OR(A17="",B17=""),"",IFERROR(XLOOKUP(1,(Order_History!$A$2:$A$501=A17)*(Order_History!$B$2:$B$501=B17),Order_History!$D$2:$D$501,""),"")) | G17: =IF(COUNTIFS(Pricing!$A:$A,A17,Pricing!$B:$B,B17)=0,"",SUMIFS(Pricing!$G:$G,Pricing!$A:$A,A17,Pricing!$B:$B,B17)) | H17: =IF(OR(E17="",F17=""),"",F17-E17) | I17: 0 | J17: 0 | K17: =IF(H17="","",H17-I17-J17) | L17: =IF(OR(K17="",E17=""),"",K17/E17) | M17: =IF(OR(C17="",D17=""),"",MAX(1,ROUNDUP(D17-C17,0))) | N17: =IF(OR(L17="",M17=""),"",(1+L17)^(365/M17)-1)
